<?xml version="1.0" ?>
<!-- =================================================================================== -->
<!-- |    This document was autogenerated by xacro from r2.urdf.xacro                  | -->
<!-- |    EDITING THIS FILE BY HAND IS NOT RECOMMENDED                                 | -->
<!-- =================================================================================== -->
<robot name="r2a" xmlns:controller="http://playerstage.sourceforge.net/gazebo/xmlschema/#controller" xmlns:interface="http://playerstage.sourceforge.net/gazebo/xmlschema/#interface" xmlns:sensor="http://playerstage.sourceforge.net/gazebo/xmlschema/#sensor" xmlns:xacro="http://ros.org/wiki/xacro">
  <material name="white">
    <color rgba="1.0 1.0 1.0 1.0"/>
  </material>
  <material name="dirty_white">
    <color rgba="0.856 0.856 0.856 1.0"/>
  </material>
  <material name="gold">
    <color rgba=".878 .49 0.008 1"/>
  </material>
  <material name="steel">
    <color rgba=".7 .7 .7 1"/>
  </material>
  <material name="blue">
    <color rgba="0 0 0.8 1"/>
  </material>
  <link name="world"/>
  <link name="dummy">
    <inertial>
      <mass value="1"/>
      <inertia ixx="1" ixy="0.0" ixz="0.0" iyy="1" iyz="0.0" izz="1"/>
    </inertial>
  </link>
  <link name="baseplate">
    <visual>
      <geometry>
        <mesh filename="package://r2_description/meshes/Stanchion_Baseplate.dae"/>
      </geometry>
      <origin rpy="1.57 0 1.57" xyz="0.0 0.0 0.0"/>
    </visual>
    <collision>
      <geometry>
        <mesh filename="package://r2_description/meshes/Stanchion_Baseplate.dae" scale=".01 .01 .01"/>
      </geometry>
      <origin rpy="1.57 0 1.57" xyz="0.0 0.0 0.0"/>
    </collision>
    <inertial>
      <mass value="5"/>
      <inertia ixx="1" ixy="0.0" ixz="0.0" iyy="1" iyz="0.0" izz="1"/>
    </inertial>
  </link>
  <link name="base">
    <visual>
      <geometry>
        <mesh filename="package://r2_description/meshes/Stanchion.dae"/>
      </geometry>
      <origin rpy="0 0 0" xyz="0.0 0.0 0.0"/>
    </visual>
    <collision>
      <geometry>
        <!--        <mesh filename="package://r2_description/meshes/Stanchion.dae"/> -->
        <cylinder length="0.5" radius=".075"/>
      </geometry>
      <origin rpy="0 0 0" xyz="0.0 0.0 -0.3"/>
    </collision>
    <inertial>
      <mass value="50"/>
      <inertia ixx="10" ixy="0.0" ixz="0.0" iyy="10" iyz="0.0" izz="10"/>
    </inertial>
  </link>
  <joint name="world/dummy" type="fixed">
    <parent link="world"/>
    <child link="dummy"/>
    <origin rpy="0.0 0 0" xyz="0.0 0.0 0.0"/>
  </joint>
  <joint name="base/b0" type="fixed">
    <parent link="dummy"/>
    <child link="baseplate"/>
    <origin rpy="0.0 0 1.57" xyz="0.0 0.0 0.0"/>
  </joint>
  <joint name="base/b1" type="fixed">
    <parent link="baseplate"/>
    <child link="base"/>
    <origin rpy="0 0 3.14" xyz="0.0 0.0 .70"/>
  </joint>
  <link name="robot_base">
    <inertial>
      <mass value="0.01"/>
      <inertia ixx="0.0001" ixy="0.0" ixz="0.0" iyy="0.001" iyz="0.0" izz="0.001"/>
    </inertial>
  </link>
  <link name="waist_center">
    <visual>
      <geometry>
        <mesh filename="package://r2_description/meshes/Body.dae"/>
      </geometry>
      <origin rpy="-1.57 0 -1.57" xyz="0.02 0.05 -0.5625"/>
    </visual>
    <collision>
      <geometry>
        <mesh filename="package://r2_description/meshes/Body.dae"/>
      </geometry>
      <origin rpy="-1.57 0 -1.57" xyz="0.02 0.05 -0.5625"/>
    </collision>
    <inertial>
      <mass value="10"/>
      <inertia ixx="1" ixy="0.0" ixz="0.0" iyy="1" iyz="0.0" izz="1"/>
    </inertial>
  </link>
  <link name="robot_reference">
    <inertial>
      <mass value="0.01"/>
      <inertia ixx="0.0001" ixy="0.0" ixz="0.0" iyy="0.001" iyz="0.0" izz="0.001"/>
    </inertial>
  </link>
  <link name="body_cover">
    <visual>
      <geometry>
        <mesh filename="package://r2_description/meshes/Body_Cover.dae"/>
      </geometry>
      <origin rpy="-1.57 0 -1.57" xyz="0.02 0.05 -0.5625"/>
    </visual>
    <collision>
      <geometry>
        <mesh filename="package://r2_description/meshes/Body_Cover.dae"/>
      </geometry>
      <origin rpy="-1.57 0 -1.57" xyz="0.02 0.05 -0.5625"/>
    </collision>
    <inertial>
      <mass value="0.1"/>
      <inertia ixx="0.001" ixy="0.0" ixz="0.0" iyy="0.001" iyz="0.0" izz="0.001"/>
    </inertial>
  </link>
  <link name="backpack">
    <visual>
      <geometry>
        <mesh filename="package://r2_description/meshes/Backpack.dae"/>
      </geometry>
      <origin rpy="0 0 0.25" xyz="0.0 0.0 -0.54"/>
    </visual>
    <collision>
      <geometry>
        <mesh filename="package://r2_description/meshes/Backpack.dae"/>
      </geometry>
      <origin rpy="0 0 0.25" xyz="0.0 0.0 -0.54"/>
    </collision>
    <inertial>
      <mass value="10"/>
      <inertia ixx="1" ixy="0.0" ixz="0.0" iyy="1" iyz="0.0" izz="1"/>
    </inertial>
  </link>
  <link name="chest_center">
    <inertial>
      <mass value="0.01"/>
      <inertia ixx="0.0001" ixy="0.0" ixz="0.0" iyy="0.001" iyz="0.0" izz="0.001"/>
    </inertial>
  </link>
  <link name="chest_base">
    <inertial>
      <mass value="0.01"/>
      <inertia ixx="0.0001" ixy="0.0" ixz="0.0" iyy="0.001" iyz="0.0" izz="0.001"/>
    </inertial>
  </link>
  <joint name="robot/j0" type="fixed">
    <parent link="base"/>
    <child link="robot_base"/>
    <origin rpy="0 3.14 3.14" xyz="0.0 0.0 0.02"/>
  </joint>
  <joint name="waist/j0" type="revolute">
    <parent link="robot_base"/>
    <child link="waist_center"/>
    <axis xyz="0 0 1"/>
    <origin rpy="0.0 0 0.0" xyz="0.0 0.0 0.0"/>
    <dynamics damping="10.0"/>
    <limit effort="10000000.0" lower="-3.14" upper="3.14" velocity="1000"/>
  </joint>
  <joint name="robot/j1" type="fixed">
    <parent link="waist_center"/>
    <child link="robot_reference"/>
    <origin rpy="0.0 0 0.0" xyz="0.1234 0.0 0.0"/>
  </joint>
  <joint name="body/j0" type="fixed">
    <parent link="waist_center"/>
    <child link="body_cover"/>
    <origin rpy="0.0 0.0 0.0" xyz="0 0.0 0.0"/>
  </joint>
  <joint name="backpack/j0" type="fixed">
    <parent link="waist_center"/>
    <child link="backpack"/>
    <origin rpy="0.0 0.0 0.0" xyz="0 0.0 0.0"/>
  </joint>
  <joint name="chest/j0" type="fixed">
    <parent link="waist_center"/>
    <child link="chest_center"/>
    <origin rpy="0.0 0.0 0.0" xyz="-0.01235 0.0 0.0"/>
  </joint>
  <joint name="chest/j1" type="fixed">
    <parent link="chest_center"/>
    <child link="chest_base"/>
    <origin rpy="0.0 -0.0 0.0 " xyz="-0.05299202 -0.0 -0.5442458"/>
  </joint>
  <link name="neck_base">
    <visual>
      <geometry>
        <mesh filename="package://r2_description/meshes/Neck_Lower.dae"/>
      </geometry>
      <origin rpy="-1.57 1.57 0" xyz="0.0 0.0 0.0"/>
    </visual>
    <inertial>
      <mass value=".1"/>
      <inertia ixx=".0010" ixy="0.0" ixz="0.0" iyy=".0010" iyz="0.0" izz=".0010"/>
    </inertial>
    <collision>
      <geometry>
        <mesh filename="package://r2_description/meshes/Neck_Lower.dae"/>
      </geometry>
      <origin rpy="-1.57 1.57 0" xyz="0.0 0.0 0.0"/>
    </collision>
  </link>
  <link name="neck_lower_pitch">
    <visual>
      <geometry>
        <mesh filename="package://r2_description/meshes/Neck_Upper.dae"/>
      </geometry>
      <origin rpy="0 0 1.57" xyz="0.075 0.0 0.0"/>
    </visual>
    <inertial>
      <mass value=".1"/>
      <inertia ixx=".0010" ixy="0.0" ixz="0.0" iyy=".0010" iyz="0.0" izz=".0010"/>
    </inertial>
    <collision>
      <geometry>
        <mesh filename="package://r2_description/meshes/Neck_Upper.dae"/>
      </geometry>
      <origin rpy="0 0 1.57" xyz="0.075 0.0 0.0"/>
    </collision>
  </link>
  <link name="neck_roll">
    <visual>
      <geometry>
        <mesh filename="package://r2_description/meshes/Head.dae"/>
      </geometry>
      <origin rpy="0 1.57 0" xyz="-0.0 0.07 0.0"/>
    </visual>
    <collision>
      <geometry>
        <mesh filename="package://r2_description/meshes/Head.dae"/>
      </geometry>
      <origin rpy="0 1.57 0" xyz="-0.0 0.07 0.0"/>
    </collision>
    <inertial>
      <mass value=".1"/>
      <inertia ixx=".0010" ixy="0.0" ixz="0.0" iyy=".0010" iyz="0.0" izz=".0010"/>
    </inertial>
  </link>
  <link name="neck_upper_pitch">
    <inertial>
      <mass value=".1"/>
      <inertia ixx=".0010" ixy="0.0" ixz="0.0" iyy=".0010" iyz="0.0" izz=".0010"/>
    </inertial>
  </link>
  <link name="simulated_asus_frame">
    <inertial>
      <mass value=".01"/>
      <inertia ixx=".0010" ixy="0.0" ixz="0.0" iyy=".0010" iyz="0.0" izz=".0010"/>
    </inertial>
  </link>
  <link name="asus_frame">
    <inertial>
      <mass value=".01"/>
      <inertia ixx=".0010" ixy="0.0" ixz="0.0" iyy=".0010" iyz="0.0" izz=".0010"/>
    </inertial>
  </link>
  <link name="openni_depth_frame">
    <inertial>
      <mass value=".01"/>
      <inertia ixx=".0010" ixy="0.0" ixz="0.0" iyy=".0010" iyz="0.0" izz=".0010"/>
    </inertial>
  </link>
  <link name="vision_center_frame">
    <inertial>
      <mass value=".1"/>
      <inertia ixx=".0010" ixy="0.0" ixz="0.0" iyy=".0010" iyz="0.0" izz=".0010"/>
    </inertial>
  </link>
  <link name="left_camera_frame">
    <inertial>
      <mass value=".1"/>
      <inertia ixx=".0010" ixy="0.0" ixz="0.0" iyy=".0010" iyz="0.0" izz=".0010"/>
    </inertial>
  </link>
  <link name="right_camera_frame">
    <inertial>
      <mass value=".1"/>
      <inertia ixx=".0010" ixy="0.0" ixz="0.0" iyy=".0010" iyz="0.0" izz=".0010"/>
    </inertial>
  </link>
  <link name="left_camera_optical_frame">
    <inertial>
      <mass value=".1"/>
      <inertia ixx=".0010" ixy="0.0" ixz="0.0" iyy=".0010" iyz="0.0" izz=".0010"/>
    </inertial>
  </link>
  <link name="right_camera_optical_frame">
    <inertial>
      <mass value=".1"/>
      <inertia ixx=".0010" ixy="0.0" ixz="0.0" iyy=".0010" iyz="0.0" izz=".0010"/>
    </inertial>
  </link>
  <joint name="neck/j0" type="revolute">
    <parent link="waist_center"/>
    <child link="neck_base"/>
    <origin rpy=" -1.570796 -0.0 0.0 " xyz=" 0.08636 0.0 -0.6142228 "/>
    <dynamics damping="1.0"/>
    <axis xyz="0 0 1"/>
    <limit effort="100000.0" lower="-0.7" upper="0.175" velocity="1000"/>
  </joint>
  <joint name="neck/j1" type="revolute">
    <parent link="neck_base"/>
    <child link="neck_lower_pitch"/>
    <origin rpy=" -1.570796 -0.0 0.0 " xyz=" -0.0762 -0.0 0.0 "/>
    <dynamics damping="1.0"/>
    <axis xyz="0 0 1"/>
    <limit effort="100000.0" lower="-1.22" upper="1.22" velocity="1000"/>
  </joint>
  <joint name="neck/j2" type="revolute">
    <parent link="neck_lower_pitch"/>
    <child link="neck_roll"/>
    <origin rpy=" 1.570796 -0.0 0.0 " xyz=" 0.0508 0.0 0.1777619 "/>
    <dynamics damping="1.0"/>
    <axis xyz="0 0 1"/>
    <limit effort="100000.0" lower="-0.7" upper="0.175" velocity="1000"/>
  </joint>
  <joint name="head" type="fixed">
    <parent link="neck_roll"/>
    <child link="neck_upper_pitch"/>
    <origin rpy=" 1.570796 -0.0 0.0 " xyz=" 0.0 0.0 0.0 "/>
  </joint>
  <joint name="asus" type="fixed">
    <parent link="neck_upper_pitch"/>
    <child link="asus_frame"/>
    <origin rpy="1.50 0.0 1.57 " xyz="0.12 -0.015 -0.14 "/>
    <!-- OK    <origin rpy="1.45 0 1.57 " xyz="0.11 -0.040 -0.15 "/>  -->
    <!-- ORIGINAL     <origin rpy="1.57 0 1.57 " xyz="0.066675 -0.0508 -0.116205 "/>  -->
  </joint>
  <joint name="openni" type="fixed">
    <parent link="asus_frame"/>
    <child link="openni_depth_frame"/>
    <origin rpy="1.57 -1.57 0 " xyz="0 0 0 "/>
  </joint>
  <joint name="simulated_asus" type="fixed">
    <parent link="neck_upper_pitch"/>
    <child link="simulated_asus_frame"/>
    <dynamics damping="1.0"/>
    <origin rpy="0 0 0" xyz="0.12 -0.015 -0.14 "/>
  </joint>
  <joint name="vision" type="fixed">
    <parent link="neck_upper_pitch"/>
    <child link="vision_center_frame"/>
    <dynamics damping="1.0"/>
    <origin rpy="1.57 -1.57 1.57" xyz=" 0.066675 0.0 -0.116205 "/>
  </joint>
  <joint name="vision_right" type="fixed">
    <parent link="vision_center_frame"/>
    <child link="right_camera_frame"/>
    <dynamics damping="1.0"/>
    <origin rpy="0 0 1.57" xyz="0.0087 -0.04887 0.01789"/>
  </joint>
  <joint name="vision_left" type="fixed">
    <parent link="vision_center_frame"/>
    <child link="left_camera_frame"/>
    <dynamics damping="1.0"/>
    <origin rpy="0 0 1.57" xyz="0.0087 0.04887 0.01789"/>
  </joint>
  <joint name="right_optical" type="fixed">
    <parent link="right_camera_frame"/>
    <child link="right_camera_optical_frame"/>
    <dynamics damping="1.0"/>
    <origin rpy="-1.57 -1.57 0" xyz="0 0 0"/>
  </joint>
  <joint name="left_optical" type="fixed">
    <parent link="left_camera_frame"/>
    <child link="left_camera_optical_frame"/>
    <dynamics damping="1.0"/>
    <origin rpy="-1.57 -1.57 0" xyz="0 0 0"/>
  </joint>
  <link name="left_shoulder_roll">
    <visual>
      <geometry>
        <mesh filename="package://r2_description/meshes/Left_Shoulder_Upper.dae"/>
      </geometry>
      <material name="dirty_white"/>
      <origin rpy="0 0 1.57" xyz="0 0 .08"/>
    </visual>
    <collision>
      <geometry>
        <mesh filename="package://r2_description/meshes/Left_Shoulder_Upper.dae"/>
      </geometry>
      <origin rpy="0 0 1.57" xyz="0 0 .08"/>
    </collision>
    <inertial>
      <origin xyz="-0.0089916 -0.00131572   0.10287   "/>
      <mass value="6.168856232"/>
      <inertia ixx="0.0198585269" ixy="-0.0060195977" ixz="-0.0003950635" iyy="0.0671900643" iyz="0.00012683" izz="0.0634150128"/>
    </inertial>
  </link>
  <link name="left_shoulder_pitch">
    <visual>
      <geometry>
        <mesh filename="package://r2_description/meshes/Left_Shoulder_Lower.dae"/>
      </geometry>
      <material name="dirty_white"/>
      <origin rpy=".0 0 -1.57" xyz="0 0 0"/>
    </visual>
    <collision>
      <geometry>
        <mesh filename="package://r2_description/meshes/Left_Shoulder_Lower.dae"/>
      </geometry>
      <origin rpy=".0 0 -1.57" xyz="0 0 0"/>
    </collision>
    <inertial>
      <origin xyz="0.037084 -0.00028448   0.0077978   "/>
      <mass value="4.4270615312"/>
      <inertia ixx="0.02701064" ixy="0.001512947" ixz="-0.000052382497887" iyy="0.0113836825" iyz="0.0000217138622526" izz="0.0251962741"/>
    </inertial>
  </link>
  <link name="left_upper_arm">
    <visual>
      <geometry>
        <mesh filename="package://r2_description/meshes/Left_Upper_Arm.dae"/>
      </geometry>
      <material name="dirty_white"/>
      <origin rpy="0 0 3.14" xyz="0 0 .1016"/>
    </visual>
    <collision>
      <geometry>
        <mesh filename="package://r2_description/meshes/Left_Upper_Arm.dae"/>
      </geometry>
      <origin rpy="0 0 3.14" xyz="0 0 .1016"/>
    </collision>
    <inertial>
      <origin xyz="-0.0074168 -0.041402   0.1016   "/>
      <mass value="4.853438359"/>
      <inertia ixx="0.016007389" ixy="-0.00339462" ixz="0.0065843922" iyy="0.0462370652" iyz="0.0013754064" izz="0.04214011"/>
    </inertial>
  </link>
  <link name="left_elbow">
    <visual>
      <geometry>
        <mesh filename="package://r2_description/meshes/Left_Elbow.dae"/>
      </geometry>
      <material name="dirty_white"/>
      <origin rpy="0 0 -1.57" xyz="0 0 0"/>
    </visual>
    <collision>
      <geometry>
        <mesh filename="package://r2_description/meshes/Left_Elbow.dae"/>
      </geometry>
      <origin rpy="0 0 -1.57" xyz="0 0 0"/>
    </collision>
    <inertial>
      <origin xyz="0.026162 0.033782   0.0154432   "/>
      <mass value="2.9710300235"/>
      <inertia ixx="0.0120274897" ixy="0.0016417085" ixz="-0.001188117" iyy="0.0088377175" iyz="0.0031605083" izz="0.0105350275"/>
    </inertial>
  </link>
  <link name="left_lower_arm">
    <visual>
      <geometry>
        <mesh filename="package://r2_description/meshes/Left_Forearm.dae"/>
      </geometry>
      <origin xyz="0 0 0.1"/>
      <material name="dirty_white"/>
    </visual>
    <collision>
      <geometry>
        <mesh filename="package://r2_description/meshes/Left_Forearm.dae"/>
      </geometry>
      <origin xyz="0 0 0.1"/>
    </collision>
    <inertial>
      <origin xyz="0.0003556 -0.00122682   0.17653   "/>
      <mass value="6.939963261"/>
      <inertia ixx="0.0125249771" ixy="-0.0002446467" ixz="0.0005208986" iyy="0.0395063532" iyz="-0.0001691457" izz="0.0403842721"/>
    </inertial>
  </link>
  <link name="left_wrist_pitch">
    <inertial>
      <origin xyz="-0.004064   0.000000152908   -0.00092202"/>
      <mass value="0.1165732391"/>
      <inertia ixx="0.00005765" ixy="0.00000000004360" ixz="0.00000175876" iyy="0.0000169438359087" iyz="0.000000054430975458" izz="0.000044188587603"/>
    </inertial>
  </link>
  <link name="left_wrist_yaw">
    <inertial>
      <origin xyz="-0.00090932   -0.0253746  0.067564     "/>
      <mass value="1.1884120094"/>
      <inertia ixx="0.0044481227" ixy="0.0003716524" ixz="0.0001024239" iyy="0.0030141884" iyz="0.000101546" izz="0.001992876"/>
    </inertial>
  </link>
  <link name="left_palm">
    <visual>
      <geometry>
        <mesh filename="package://r2_description/meshes/Left_Palm.dae"/>
      </geometry>
      <origin rpy="3.14 0 1.57" xyz="0.0 0.0 -0.0"/>
    </visual>
    <collision>
      <geometry>
        <mesh filename="package://r2_description/meshes/Left_Palm.dae"/>
      </geometry>
      <origin rpy="3.14 0 1.57" xyz="0.0 0.0 -0.0"/>
    </collision>
    <inertial>
      <origin xyz="0.067564   -0.0253746   -0.00090932"/>
      <mass value="1.1884120094"/>
      <inertia ixx="0.001992876" ixy="0.000101546" ixz="0.0001024239" iyy="0.0030141884" iyz="0.0003716524" izz="0.0044481227"/>
    </inertial>
  </link>
  <joint name="left/j0" type="revolute">
    <parent link="chest_base"/>
    <child link="left_shoulder_roll"/>
    <origin rpy=" -1.5664 -0.0 -2.8802 " xyz=" -0.0 -0.0 0.0 "/>
    <axis xyz="0 0 1"/>
    <dynamics damping="10.0"/>
    <limit effort="100.0" lower="-1.57" upper="1.57" velocity="1000"/>
  </joint>
  <joint name="left/j1" type="revolute">
    <parent link="left_shoulder_roll"/>
    <child link="left_shoulder_pitch"/>
    <origin rpy=" -1.5701 -0.0 1.570796 " xyz=" 0.0 0.0 0.316611 "/>
    <axis xyz="0 0 1"/>
    <dynamics damping="10.0"/>
    <limit effort="100.0" lower="-1.66" upper=".175" velocity="1000"/>
  </joint>
  <joint name="left/j2" type="revolute">
    <parent link="left_shoulder_pitch"/>
    <child link="left_upper_arm"/>
    <origin rpy=" 1.57 -0.0 0.0 " xyz=" 0.0 0.0 0.0 "/>
    <axis xyz="0 0 1"/>
    <dynamics damping="1.0"/>
    <!-- limits expanded because Gazebo starts up at zero causing stability issues-->
    <!--    <limit effort="100.0" lower="-4.89" upper="-0.79" velocity="1000"/>-->
    <limit effort="100.0" lower="-5.68" upper="0.0" velocity="1000"/>
  </joint>
  <joint name="left/j3" type="revolute">
    <parent link="left_upper_arm"/>
    <child link="left_elbow"/>
    <origin rpy=" -1.5748 -0.0 0.0 " xyz=" -0.05437886 -0.0 0.3564382 "/>
    <axis xyz="0 0 1"/>
    <dynamics damping="1.0"/>
    <!-- limits expanded because Gazebo starts up at zero causing stability issues-->
    <!--    <limit effort="100.0" lower="-2.79" upper="-.087" velocity="1000"/>-->
    <limit effort="100.0" lower="-2.877" upper="0.0" velocity="1000"/>
  </joint>
  <joint name="left/j4" type="revolute">
    <parent link="left_elbow"/>
    <child link="left_lower_arm"/>
    <origin rpy=" 1.5738 -0.0 0.0 " xyz=" 0.0540385 0.0 0.0 "/>
    <axis xyz="0 0 1"/>
    <dynamics damping="1.0"/>
    <limit effort="100.0" lower="-1.3" upper="4.45" velocity="1000"/>
  </joint>
  <joint name="left/j5" type="revolute">
    <parent link="left_lower_arm"/>
    <child link="left_wrist_pitch"/>
    <origin rpy=" -1.5952 -0.0 0.0 " xyz=" 0.0 0.0 0.3570478 "/>
    <axis xyz="0 0 1"/>
    <dynamics damping="1.0"/>
    <limit effort="100.0" lower="-1.22" upper="1.22" velocity="1000"/>
  </joint>
  <joint name="left/j6" type="revolute">
    <parent link="left_wrist_pitch"/>
    <child link="left_wrist_yaw"/>
    <origin rpy=" 1.6505 -0.0 -1.5727 " xyz=" -0.00001156 -0.006072621 0.0 "/>
    <axis xyz="0 0 1"/>
    <dynamics damping="1.0"/>
    <limit effort="100.0" lower="-0.785" upper="0.785" velocity="1000"/>
  </joint>
  <joint name="left/j7" type="fixed">
    <parent link="left_wrist_yaw"/>
    <child link="left_palm"/>
    <origin rpy=" 0.0 -0.0 -0.014 " xyz=" 0.0 -0.0 0.0 "/>
  </joint>
  <link name="left_thumb_base">
    <inertial>
      <mass value=".05"/>
      <inertia ixx=".0010" ixy="0.0" ixz="0.0" iyy=".0010" iyz="0.0" izz=".0010"/>
    </inertial>
  </link>
  <link name="left_thumb_proximal">
    <inertial>
      <mass value=".0010"/>
      <inertia ixx=".0010" ixy="0.0" ixz="0.0" iyy=".0010" iyz="0.0" izz=".0010"/>
    </inertial>
    <visual>
      <geometry>
        <mesh filename="package://r2_description/meshes/Left_Thumb_Carp.dae"/>
      </geometry>
      <origin rpy="-1.57 0 0" xyz="-0.01 0.0 0.0"/>
    </visual>
    <collision>
      <geometry>
        <mesh filename="package://r2_description/meshes/Left_Thumb_Carp.dae"/>
      </geometry>
      <origin rpy="-1.57 0 0" xyz="-0.01 0.0 0.0"/>
    </collision>
  </link>
  <link name="left_thumb_medial_prime">
    <inertial>
      <mass value=".0010"/>
      <inertia ixx=".0010" ixy="0.0" ixz="0.0" iyy=".0010" iyz="0.0" izz=".0010"/>
    </inertial>
    <visual>
      <geometry>
        <mesh filename="package://r2_description/meshes/Left_Thumb_MtCar.dae"/>
      </geometry>
      <origin rpy="-1.57 -1.57 0" xyz="-0.0 0 0.0"/>
    </visual>
    <collision>
      <geometry>
        <mesh filename="package://r2_description/meshes/Left_Thumb_MtCar.dae"/>
      </geometry>
      <origin rpy="-1.57 -1.57 0" xyz="0.0 0.0 0.0"/>
    </collision>
  </link>
  <link name="left_thumb_medial">
    <inertial>
      <mass value=".0010"/>
      <inertia ixx=".0010" ixy="0.0" ixz="0.0" iyy=".0010" iyz="0.0" izz=".0010"/>
    </inertial>
    <visual>
      <geometry>
        <mesh filename="package://r2_description/meshes/Thumb_Proximal.dae"/>
      </geometry>
      <origin rpy="3.14 0 1.57" xyz="0.0 0.0 0.0"/>
    </visual>
    <collision>
      <geometry>
        <mesh filename="package://r2_description/meshes/Thumb_Proximal.dae"/>
      </geometry>
      <origin rpy="3.14 0 1.57" xyz="0.0 0.0 0.0"/>
    </collision>
  </link>
  <link name="left_thumb_distal">
    <inertial>
      <mass value=".0010"/>
      <inertia ixx=".0010" ixy="0.0" ixz="0.0" iyy=".0010" iyz="0.0" izz=".0010"/>
    </inertial>
    <visual>
      <geometry>
        <mesh filename="package://r2_description/meshes/Thumb_Dist.dae"/>
      </geometry>
      <origin rpy="3.14 3.14 0" xyz="0.0 0.0 0.0"/>
    </visual>
    <collision>
      <geometry>
        <mesh filename="package://r2_description/meshes/Thumb_Dist.dae"/>
      </geometry>
      <origin rpy="3.14 3.14 0" xyz="0.0 0.0 0.0"/>
    </collision>
  </link>
  <link name="left_thumb_tip">
    <inertial>
      <mass value=".0010"/>
      <inertia ixx=".0010" ixy="0.0" ixz="0.0" iyy=".0010" iyz="0.0" izz=".0010"/>
    </inertial>
  </link>
  <link name="left_index_base">
    <inertial>
      <mass value=".0010"/>
      <inertia ixx=".0010" ixy="0.0" ixz="0.0" iyy=".0010" iyz="0.0" izz=".0010"/>
    </inertial>
  </link>
  <link name="left_index_proximal">
    <inertial>
      <mass value=".0010"/>
      <inertia ixx=".0010" ixy="0.0" ixz="0.0" iyy=".0010" iyz="0.0" izz=".0010"/>
    </inertial>
    <visual>
      <geometry>
        <mesh filename="package://r2_description/meshes/Finger_Proximal.dae"/>
      </geometry>
      <origin rpy="0 0 1.57" xyz="0.0 0.0 0.0"/>
    </visual>
    <collision>
      <geometry>
        <mesh filename="package://r2_description/meshes/Finger_Proximal.dae"/>
      </geometry>
      <origin rpy="0 0 1.57" xyz="0.0 0.0 0.0"/>
    </collision>
  </link>
  <link name="left_index_medial">
    <inertial>
      <mass value=".0010"/>
      <inertia ixx=".0010" ixy="0.0" ixz="0.0" iyy=".0010" iyz="0.0" izz=".0010"/>
    </inertial>
    <visual>
      <geometry>
        <mesh filename="package://r2_description/meshes/Finger_Mid.dae"/>
      </geometry>
      <origin rpy="3.14 0 1.57" xyz="0.0 0.0 0.0"/>
    </visual>
    <collision>
      <geometry>
        <mesh filename="package://r2_description/meshes/Finger_Mid.dae"/>
      </geometry>
      <origin rpy="3.14 0 1.57" xyz="0.0 0.0 0.0"/>
    </collision>
  </link>
  <link name="left_index_distal">
    <inertial>
      <mass value=".0010"/>
      <inertia ixx=".0010" ixy="0.0" ixz="0.0" iyy=".0010" iyz="0.0" izz=".0010"/>
    </inertial>
    <visual>
      <geometry>
        <mesh filename="package://r2_description/meshes/Finger_Dist.dae"/>
      </geometry>
      <origin rpy="0 -1.57 0" xyz="0.0 0.0 0.0"/>
    </visual>
    <collision>
      <geometry>
        <mesh filename="package://r2_description/meshes/Finger_Dist.dae"/>
      </geometry>
      <origin rpy="0 -1.57 0" xyz="0.0 0.0 0.0"/>
    </collision>
  </link>
  <link name="left_index_tip">
    <inertial>
      <mass value=".0010"/>
      <inertia ixx=".0010" ixy="0.0" ixz="0.0" iyy=".0010" iyz="0.0" izz=".0010"/>
    </inertial>
  </link>
  <link name="left_middle_base">
    <inertial>
      <mass value=".0010"/>
      <inertia ixx=".0010" ixy="0.0" ixz="0.0" iyy=".0010" iyz="0.0" izz=".0010"/>
    </inertial>
  </link>
  <link name="left_middle_proximal">
    <inertial>
      <mass value=".0010"/>
      <inertia ixx=".0010" ixy="0.0" ixz="0.0" iyy=".0010" iyz="0.0" izz=".0010"/>
    </inertial>
    <visual>
      <geometry>
        <mesh filename="package://r2_description/meshes/Finger_Proximal.dae"/>
      </geometry>
      <origin rpy="0 0 1.57" xyz="0.0 0.0 0.0"/>
    </visual>
    <collision>
      <geometry>
        <mesh filename="package://r2_description/meshes/Finger_Proximal.dae"/>
      </geometry>
      <origin rpy="0 0 1.57" xyz="0.0 0.0 0.0"/>
    </collision>
  </link>
  <link name="left_middle_medial">
    <inertial>
      <mass value=".0010"/>
      <inertia ixx=".0010" ixy="0.0" ixz="0.0" iyy=".0010" iyz="0.0" izz=".0010"/>
    </inertial>
    <visual>
      <geometry>
        <mesh filename="package://r2_description/meshes/Finger_Mid.dae"/>
      </geometry>
      <origin rpy="3.14 0 1.57" xyz="0.0 0.0 0.0"/>
    </visual>
    <collision>
      <geometry>
        <mesh filename="package://r2_description/meshes/Finger_Mid.dae"/>
      </geometry>
      <origin rpy="3.14 0 1.57" xyz="0.0 0.0 0.0"/>
    </collision>
  </link>
  <link name="left_middle_distal">
    <inertial>
      <mass value=".0010"/>
      <inertia ixx=".0010" ixy="0.0" ixz="0.0" iyy=".0010" iyz="0.0" izz=".0010"/>
    </inertial>
    <visual>
      <geometry>
        <mesh filename="package://r2_description/meshes/Finger_Dist.dae"/>
      </geometry>
      <origin rpy="0 -1.57 0" xyz="0.0 0.0 0.0"/>
    </visual>
    <collision>
      <geometry>
        <mesh filename="package://r2_description/meshes/Finger_Dist.dae"/>
      </geometry>
      <origin rpy="0 -1.57 0" xyz="0.0 0.0 0.0"/>
    </collision>
  </link>
  <link name="left_middle_tip">
    <inertial>
      <mass value=".0010"/>
      <inertia ixx=".0010" ixy="0.0" ixz="0.0" iyy=".0010" iyz="0.0" izz=".0010"/>
    </inertial>
  </link>
  <link name="left_ring_proximal">
    <inertial>
      <mass value=".0010"/>
      <inertia ixx=".0010" ixy="0.0" ixz="0.0" iyy=".0010" iyz="0.0" izz=".0010"/>
    </inertial>
    <visual>
      <geometry>
        <mesh filename="package://r2_description/meshes/Finger_Proximal.dae"/>
      </geometry>
      <origin rpy="0 0 1.57" xyz="0.0 0.0 0.0"/>
    </visual>
    <collision>
      <geometry>
        <mesh filename="package://r2_description/meshes/Finger_Proximal.dae"/>
      </geometry>
      <origin rpy="0 0 1.57" xyz="0.0 0.0 0.0"/>
    </collision>
  </link>
  <link name="left_ring_medial">
    <inertial>
      <mass value=".0010"/>
      <inertia ixx=".0010" ixy="0.0" ixz="0.0" iyy=".0010" iyz="0.0" izz=".0010"/>
    </inertial>
    <visual>
      <geometry>
        <mesh filename="package://r2_description/meshes/Finger_Mid.dae"/>
      </geometry>
      <origin rpy="3.14 0 1.57" xyz="0.0 0.0 0.0"/>
    </visual>
    <collision>
      <geometry>
        <mesh filename="package://r2_description/meshes/Finger_Mid.dae"/>
      </geometry>
      <origin rpy="3.14 0 1.57" xyz="0.0 0.0 0.0"/>
    </collision>
  </link>
  <link name="left_ring_distal">
    <inertial>
      <mass value=".0010"/>
      <inertia ixx=".0010" ixy="0.0" ixz="0.0" iyy=".0010" iyz="0.0" izz=".0010"/>
    </inertial>
    <visual>
      <geometry>
        <mesh filename="package://r2_description/meshes/Finger_Dist.dae"/>
      </geometry>
      <origin rpy="0 -1.57 0" xyz="0.0 0.0 0.0"/>
    </visual>
    <collision>
      <geometry>
        <mesh filename="package://r2_description/meshes/Finger_Dist.dae"/>
      </geometry>
      <origin rpy="0 -1.57 0" xyz="0.0 0.0 0.0"/>
    </collision>
  </link>
  <link name="left_ring_tip">
    <inertial>
      <mass value=".0010"/>
      <inertia ixx=".0010" ixy="0.0" ixz="0.0" iyy=".0010" iyz="0.0" izz=".0010"/>
    </inertial>
  </link>
  <link name="left_little_proximal">
    <inertial>
      <mass value=".0010"/>
      <inertia ixx=".0010" ixy="0.0" ixz="0.0" iyy=".0010" iyz="0.0" izz=".0010"/>
    </inertial>
    <visual>
      <geometry>
        <mesh filename="package://r2_description/meshes/Finger_Proximal.dae"/>
      </geometry>
      <origin rpy="0 0 1.57" xyz="0.0 0.0 0.0"/>
    </visual>
    <collision>
      <geometry>
        <mesh filename="package://r2_description/meshes/Finger_Proximal.dae"/>
      </geometry>
      <origin rpy="0 0 1.57" xyz="0.0 0.0 0.0"/>
    </collision>
  </link>
  <link name="left_little_medial">
    <inertial>
      <mass value=".0010"/>
      <inertia ixx=".0010" ixy="0.0" ixz="0.0" iyy=".0010" iyz="0.0" izz=".0010"/>
    </inertial>
    <visual>
      <geometry>
        <mesh filename="package://r2_description/meshes/Finger_Mid.dae"/>
      </geometry>
      <origin rpy="3.14 0 1.57" xyz="0.0 0.0 0.0"/>
    </visual>
    <collision>
      <geometry>
        <mesh filename="package://r2_description/meshes/Finger_Mid.dae"/>
      </geometry>
      <origin rpy="3.14 0 1.57" xyz="0.0 0.0 0.0"/>
    </collision>
  </link>
  <link name="left_little_distal">
    <inertial>
      <mass value=".0010"/>
      <inertia ixx=".0010" ixy="0.0" ixz="0.0" iyy=".0010" iyz="0.0" izz=".0010"/>
    </inertial>
    <visual>
      <geometry>
        <mesh filename="package://r2_description/meshes/Finger_Dist.dae"/>
      </geometry>
      <origin rpy="0 -1.57 0" xyz="0.0 0.0 0.0"/>
    </visual>
    <collision>
      <geometry>
        <mesh filename="package://r2_description/meshes/Finger_Dist.dae"/>
      </geometry>
      <origin rpy="0 -1.57 0" xyz="0.0 0.0 0.0"/>
    </collision>
  </link>
  <link name="left_little_tip">
    <inertial>
      <mass value=".0010"/>
      <inertia ixx=".0010" ixy="0.0" ixz="0.0" iyy=".0010" iyz="0.0" izz=".0010"/>
    </inertial>
  </link>
  <joint name="left_thumb/j0" type="revolute">
    <parent link="left_wrist_yaw"/>
    <child link="left_thumb_base"/>
    <origin rpy=" -1.57079632679 -0.0 1.30899702752 " xyz=" 0.03302 0.03048 0.00635 "/>
    <axis xyz="0 0 1"/>
    <limit effort="10000000.0" lower="-1.2217" upper="0.0" velocity="1000"/>
    <dynamics damping="0.1"/>
  </joint>
  <joint name="left_thumb/j1" type="fixed">
    <parent link="left_thumb_base"/>
    <child link="left_thumb_proximal"/>
    <origin rpy=" -1.570796 -0.0 0.0 " xyz=" 0.011938 0.0 0.0 "/>
    <dynamics damping="0.1"/>
  </joint>
  <joint name="left_thumb/j2" type="revolute">
    <parent link="left_thumb_proximal"/>
    <child link="left_thumb_medial_prime"/>
    <origin rpy=" 0.0 -0.0 0.0 " xyz=" 0.0 0.0 0.0 "/>
    <axis xyz="0 0 1"/>
    <limit effort="10000000.0" lower="0.0" upper="1.3963" velocity="1000"/>
    <dynamics damping="0.1"/>
  </joint>
  <joint name="left_thumb/j3" type="revolute">
    <parent link="left_thumb_medial_prime"/>
    <child link="left_thumb_medial"/>
    <origin rpy=" -0.698132284627 -0.0 0.0 " xyz=" 0.030734 -0.001905 0.00254 "/>
    <axis xyz="0 0 1"/>
    <limit effort="10000000.0" lower="0.0" upper="1.2217" velocity="1000"/>
    <dynamics damping="0.1"/>
  </joint>
  <joint name="left_thumb/j4" type="revolute">
    <parent link="left_thumb_medial"/>
    <child link="left_thumb_distal"/>
    <origin rpy=" 0.0 -0.0 0.0 " xyz=" 0.03937 0.0 0.0 "/>
    <axis xyz="0 0 1"/>
    <limit effort="10000000.0" lower="-0.5236" upper="1.57" velocity="1000"/>
    <dynamics damping="0.1"/>
  </joint>
  <joint name="left_thumb/j5" type="fixed">
    <parent link="left_thumb_distal"/>
    <child link="left_thumb_tip"/>
    <origin rpy=" 0.0 -0.0 0.0 " xyz=" 0.03302 0.0 0.0 "/>
    <dynamics damping="0.1"/>
  </joint>
  <joint name="left_index/j0" type="revolute">
    <parent link="left_wrist_yaw"/>
    <child link="left_index_base"/>
    <origin rpy=" 0.0 -0.0 0.122172725275 " xyz=" 0.0994646728 0.0271119346 -0.0161544 "/>
    <axis xyz="0 0 1"/>
    <limit effort="10000000.0" lower="-0.3491" upper="0.3491" velocity="1000"/>
    <dynamics damping="0.1"/>
  </joint>
  <joint name="left_index/j1" type="revolute">
    <parent link="left_index_base"/>
    <child link="left_index_proximal"/>
    <origin rpy=" 1.570796 0.0 0.0 " xyz=" 0.009652 0.0 0.0 "/>
    <axis xyz="0 0 1"/>
    <limit effort="10000000.0" lower="0.0" upper="1.57" velocity="1000"/>
    <dynamics damping="0.1"/>
  </joint>
  <joint name="left_index/j2" type="revolute">
    <parent link="left_index_proximal"/>
    <child link="left_index_medial"/>
    <origin rpy=" 0.0 -0.0 0.0 " xyz=" 0.04445 0.0 0.0 "/>
    <axis xyz="0 0 1"/>
    <limit effort="10000000.0" lower="0.0" upper="1.57" velocity="1000"/>
    <dynamics damping="0.1"/>
  </joint>
  <joint name="left_index/j3" type="revolute">
    <parent link="left_index_medial"/>
    <child link="left_index_distal"/>
    <origin rpy=" 0.0 -0.0 0.0 " xyz=" 0.03048 0.0 0.0 "/>
    <axis xyz="0 0 1"/>
    <limit effort="10000000.0" lower="0.0" upper="1.57" velocity="1000"/>
    <dynamics damping="0.1"/>
  </joint>
  <joint name="left_index/j4" type="fixed">
    <parent link="left_index_distal"/>
    <child link="left_index_tip"/>
    <origin rpy=" 0.0 -0.0 0.0 " xyz=" 0.024638 0.0 0.0 "/>
    <dynamics damping="0.1"/>
  </joint>
  <joint name="left_middle/j0" type="revolute">
    <parent link="left_wrist_yaw"/>
    <child link="left_middle_base"/>
    <origin rpy=" 0.0 -0.0 0.0 " xyz=" 0.10646537 0.00254 -0.0161544 "/>
    <axis xyz="0 0 1"/>
    <limit effort="10000000.0" lower="-0.3491" upper="0.3491" velocity="1000"/>
    <dynamics damping="0.1"/>
  </joint>
  <joint name="left_middle/j1" type="revolute">
    <parent link="left_middle_base"/>
    <child link="left_middle_proximal"/>
    <origin rpy=" 1.570796 -0.0 0.0 " xyz=" 0.009652 0.0 0.0 "/>
    <axis xyz="0 0 1"/>
    <limit effort="10000000.0" lower="0.0" upper="1.57" velocity="1000"/>
    <dynamics damping="0.1"/>
  </joint>
  <joint name="left_middle/j2" type="revolute">
    <parent link="left_middle_proximal"/>
    <child link="left_middle_medial"/>
    <origin rpy=" 0.0 -0.0 0.0 " xyz=" 0.04445 0.0 0.0 "/>
    <axis xyz="0 0 1"/>
    <limit effort="10000000.0" lower="0.0" upper="1.57" velocity="1000"/>
    <dynamics damping="0.1"/>
  </joint>
  <joint name="left_middle/j3" type="revolute">
    <parent link="left_middle_medial"/>
    <child link="left_middle_distal"/>
    <origin rpy=" 0.0 -0.0 0.0 " xyz=" 0.03048 0.0 0.0 "/>
    <axis xyz="0 0 1"/>
    <limit effort="10000000.0" lower="0.0" upper="1.57" velocity="1000"/>
    <dynamics damping="0.1"/>
  </joint>
  <joint name="left_middle/j4" type="fixed">
    <parent link="left_middle_distal"/>
    <child link="left_middle_tip"/>
    <origin rpy=" 0.0 -0.0 0.0 " xyz=" 0.024638 0.0 0.0 "/>
    <dynamics damping="0.1"/>
  </joint>
  <joint name="left_ring/j0" type="revolute">
    <parent link="left_wrist_yaw"/>
    <child link="left_ring_proximal"/>
    <origin rpy=" 1.57079632679 -0.0 -0.122172725275 " xyz=" 0.1084570602 -0.0197673468 -0.012319 "/>
    <axis xyz="0 0 1"/>
    <limit effort="10000000.0" lower="0" upper="2.9671" velocity="1000"/>
    <dynamics damping="0.1"/>
  </joint>
  <joint name="left_ring/j1" type="revolute">
    <parent link="left_ring_proximal"/>
    <child link="left_ring_medial"/>
    <origin rpy=" 0.0 -0.0 0.0 " xyz=" 0.04445 0.0 0.0 "/>
    <axis xyz="0 0 1"/>
    <limit effort="10000000.0" lower="0" upper="2.9671" velocity="1000"/>
    <dynamics damping="0.1"/>
  </joint>
  <joint name="left_ring/j2" type="revolute">
    <parent link="left_ring_medial"/>
    <child link="left_ring_distal"/>
    <origin rpy=" 0.0 -0.0 0.0 " xyz=" 0.03048 0.0 0.0 "/>
    <axis xyz="0 0 1"/>
    <limit effort="10000000.0" lower="0" upper="2.9671" velocity="1000"/>
    <dynamics damping="0.1"/>
  </joint>
  <joint name="left_ring/j3" type="fixed">
    <parent link="left_ring_distal"/>
    <child link="left_ring_tip"/>
    <origin rpy=" 0.0 -0.0 0.0 " xyz=" 0.024638 0.0 0.0 "/>
    <dynamics damping="0.1"/>
  </joint>
  <joint name="left_little/j0" type="revolute">
    <parent link="left_wrist_yaw"/>
    <child link="left_little_proximal"/>
    <origin rpy=" 1.60570321374 -0.0872667473393 -0.17453258148 " xyz=" 0.094635701 -0.0403792436 -0.0060878212 "/>
    <axis xyz="0 0 1"/>
    <limit effort="10000000.0" lower="0" upper="2.9671" velocity="1000"/>
    <dynamics damping="0.1"/>
  </joint>
  <joint name="left_little/j1" type="revolute">
    <parent link="left_little_proximal"/>
    <child link="left_little_medial"/>
    <origin rpy=" 0.0 -0.0 0.0 " xyz=" 0.04445 0.0 0.0 "/>
    <axis xyz="0 0 1"/>
    <limit effort="10000000.0" lower="0" upper="2.9671" velocity="1000"/>
    <dynamics damping="0.1"/>
  </joint>
  <joint name="left_little/j2" type="revolute">
    <parent link="left_little_medial"/>
    <child link="left_little_distal"/>
    <origin rpy=" 0.0 -0.0 0.0 " xyz=" 0.03048 0.0 0.0 "/>
    <axis xyz="0 0 1"/>
    <limit effort="10000000.0" lower="0" upper="2.9671" velocity="1000"/>
    <dynamics damping="0.1"/>
  </joint>
  <joint name="left_little/j3" type="fixed">
    <parent link="left_little_distal"/>
    <child link="left_little_tip"/>
    <origin rpy=" 0.0 -0.0 0.0 " xyz=" 0.024638 0.0 0.0 "/>
    <dynamics damping="0.1"/>
  </joint>
  <link name="right_shoulder_roll">
    <visual>
      <geometry>
        <mesh filename="package://r2_description/meshes/Right_Shoulder_Upper.dae"/>
      </geometry>
      <material name="dirty_white"/>
      <origin rpy="0 0 2.25" xyz="0 0 .0254"/>
    </visual>
    <collision>
      <geometry>
        <mesh filename="package://r2_description/meshes/Right_Shoulder_Upper.dae"/>
      </geometry>
      <origin rpy="0 0 2.35" xyz="0 0 .0254"/>
    </collision>
    <inertial>
      <origin xyz="0.0089916 -0.00131572  0.10287"/>
      <mass value="6.168856232"/>
      <inertia ixx="0.0198585269" ixy="0.0060195977" ixz="0.0003950635" iyy="0.0671900643" iyz="0.00012683" izz="0.0634150128"/>
    </inertial>
  </link>
  <link name="right_shoulder_pitch">
    <visual>
      <geometry>
        <mesh filename="package://r2_description/meshes/Right_Shoulder_Lower.dae"/>
      </geometry>
      <material name="dirty_white"/>
      <origin rpy=".0 0 1.57" xyz="0 0 0"/>
    </visual>
    <collision>
      <geometry>
        <mesh filename="package://r2_description/meshes/Right_Shoulder_Lower.dae"/>
      </geometry>
      <origin rpy=".0 0 1.57" xyz="0 0 0"/>
    </collision>
    <inertial>
      <origin xyz="0.0077978 0.037084 0.00028448"/>
      <mass value="4.4270615312"/>
      <inertia ixx="0.0113836825" ixy="-.0000217138622526" ixz="-.001512947" iyy="0.0251962741" iyz="-0.000052382497887" izz="0.02701064"/>
    </inertial>
  </link>
  <link name="right_upper_arm">
    <visual>
      <geometry>
        <mesh filename="package://r2_description/meshes/Right_Upper_Arm.dae"/>
      </geometry>
      <material name="dirty_white"/>
      <origin rpy="0 0 0" xyz="0 0 .1016"/>
    </visual>
    <collision>
      <geometry>
        <mesh filename="package://r2_description/meshes/Right_Upper_Arm.dae"/>
      </geometry>
      <origin rpy="0 0 0" xyz="0 0 .1016"/>
    </collision>
    <inertial>
      <origin xyz="0.041402  -0.0074168  0.1016"/>
      <mass value="4.853438359"/>
      <inertia ixx="0.04214011" ixy="-0.0013754064" ixz="-0.0065843922" iyy="0.0462370652" iyz="-0.00339462" izz="0.016007389"/>
    </inertial>
  </link>
  <link name="right_elbow">
    <visual>
      <geometry>
        <mesh filename="package://r2_description/meshes/Right_Elbow.dae"/>
      </geometry>
      <material name="dirty_white"/>
      <origin rpy="0 0 1.57" xyz="0 0 0"/>
    </visual>
    <collision>
      <geometry>
        <mesh filename="package://r2_description/meshes/Right_Elbow.dae"/>
      </geometry>
      <origin rpy="0 0 1.57" xyz="0 0 0"/>
    </collision>
    <inertial>
      <origin xyz=" -0.026162  0.033782 0.0154432"/>
      <mass value="2.9710300235"/>
      <inertia ixx="0.0120274897" ixy="-0.001188117" ixz="0.0016417085" iyy="0.0088377175" iyz="-0.0031605083" izz="0.0105350275"/>
    </inertial>
  </link>
  <link name="right_lower_arm">
    <visual>
      <geometry>
        <mesh filename="package://r2_description/meshes/Right_Forearm.dae"/>
      </geometry>
      <material name="dirty_white"/>
      <origin xyz="0 0 0.1"/>
    </visual>
    <collision>
      <geometry>
        <mesh filename="package://r2_description/meshes/Right_Forearm.dae"/>
      </geometry>
      <origin xyz="0 0 0.1"/>
    </collision>
    <inertial>
      <origin xyz="0.0003556 -0.00122682 0.17653"/>
      <mass value="6.939963261"/>
      <inertia ixx="0.0125249771" ixy="0.0002446467" ixz="0.0005208986" iyy="0.0395063532" iyz="0.0001691457" izz="0.0403842721"/>
    </inertial>
  </link>
  <link name="right_wrist_pitch">
    <inertial>
      <origin xyz="0.00092202 -0.004064 0.000000152908"/>
      <mass value="0.1165732391"/>
      <inertia ixx=".0000169438359087" ixy=".000000054430975458" ixz="-.000000000043603308297" iyy=".000044188587603" iyz="-.00000175876431453" izz=".00005765"/>
    </inertial>
  </link>
  <link name="right_wrist_yaw">
    <inertial>
      <origin xyz="0.067564 0.00090932 0.0253746"/>
      <mass value="1.1884120094"/>
      <inertia ixx="0.001992876" ixy="-0.0001024239" ixz="-0.000101546" iyy="0.0044481227" iyz="0.0003716524" izz="0.0030141884"/>
    </inertial>
  </link>
  <link name="right_palm">
    <visual>
      <geometry>
        <mesh filename="package://r2_description/meshes/Right_Palm.dae"/>
      </geometry>
      <origin rpy="3.14 0 1.57" xyz="0.0 0.0 -0.0"/>
    </visual>
    <collision>
      <geometry>
        <mesh filename="package://r2_description/meshes/Right_Palm.dae"/>
      </geometry>
      <origin rpy="3.14 0 1.57" xyz="0.0 0.0 -0.0"/>
    </collision>
    <inertial>
      <mass value="0.1"/>
      <inertia ixx=".0010" ixy="0.0" ixz="0.0" iyy=".0010" iyz="0.0" izz=".0010"/>
    </inertial>
  </link>
  <joint name="right/j0" type="revolute">
    <parent link="chest_base"/>
    <child link="right_shoulder_roll"/>
    <origin rpy=" -1.5596 -0.0 -0.26157" xyz=" 0.0 -0.0 0.0"/>
    <axis xyz="0 0 1"/>
    <dynamics damping="10.0"/>
    <limit effort="100.0" lower="-1.57" upper="1.57" velocity="1000"/>
  </joint>
  <joint name="right/j1" type="revolute">
    <parent link="right_shoulder_roll"/>
    <child link="right_shoulder_pitch"/>
    <origin rpy=" 1.5637 -0.0 -1.570796" xyz=" 0.0 -0.0 0.320929"/>
    <axis xyz="0 0 1"/>
    <dynamics damping="10.0"/>
    <limit effort="100.0" lower="-1.66" upper=".175" velocity="1000"/>
  </joint>
  <joint name="right/j2" type="revolute">
    <parent link="right_shoulder_pitch"/>
    <child link="right_upper_arm"/>
    <origin rpy=" -1.5679 -0.0 0.0" xyz=" 0.0 0.0 0.0"/>
    <axis xyz="0 0 1"/>
    <dynamics damping="1.0"/>
    <!-- limits expanded because Gazebo starts up at zero causing stability issues-->
    <!--    <limit effort="100.0" lower="0.785" upper="4.89" velocity="1000"/>-->
    <limit effort="100.0" lower="0.0" upper="5.675" velocity="1000"/>
  </joint>
  <joint name="right/j3" type="revolute">
    <parent link="right_upper_arm"/>
    <child link="right_elbow"/>
    <origin rpy=" 1.5684 -0.0 0.0" xyz=" 0.0536067 0.0 0.355219"/>
    <axis xyz="0 0 1"/>
    <dynamics damping="1.0"/>
    <!-- limits expanded because Gazebo starts up at zero causing stability issues-->
    <!--    <limit effort="100.0" lower="-2.79" upper="-.087" velocity="1000"/>-->
    <limit effort="100.0" lower="-2.877" upper="0.0" velocity="1000"/>
  </joint>
  <joint name="right/j4" type="revolute">
    <parent link="right_elbow"/>
    <child link="right_lower_arm"/>
    <origin rpy=" -1.5656 -0.0 0.0" xyz=" -0.0537464 -0.0 0.0"/>
    <axis xyz="0 0 1"/>
    <dynamics damping="1.0"/>
    <limit effort="100.0" lower="-4.45" upper="1.31" velocity="1000"/>
  </joint>
  <joint name="right/j5" type="revolute">
    <parent link="right_lower_arm"/>
    <child link="right_wrist_pitch"/>
    <origin rpy=" 1.5329 -0.0 0.0" xyz=" 0.0 0.0 0.3569462"/>
    <axis xyz="0 0 1"/>
    <dynamics damping="1.0"/>
    <limit effort="100.0" lower="-1.22" upper="1.22" velocity="1000"/>
  </joint>
  <joint name="right/j6" type="revolute">
    <parent link="right_wrist_pitch"/>
    <child link="right_wrist_yaw"/>
    <origin rpy=" 1.5612 -0.0 1.5923" xyz=" -0.000139607 0.006491247 0.0"/>
    <axis xyz="0 0 1"/>
    <dynamics damping="1.0"/>
    <limit effort="100.0" lower="-0.785" upper="0.785" velocity="1000"/>
  </joint>
  <joint name="right/j7" type="fixed">
    <parent link="right_wrist_yaw"/>
    <child link="right_palm"/>
    <origin rpy=" 0.0 -0.0 0.0299" xyz=" 0.0 0.0 0.0"/>
  </joint>
  <link name="right_thumb_base">
    <inertial>
      <mass value=".05"/>
      <inertia ixx=".0010" ixy="0.0" ixz="0.0" iyy=".0010" iyz="0.0" izz=".0010"/>
    </inertial>
  </link>
  <link name="right_thumb_proximal">
    <inertial>
      <mass value=".05"/>
      <inertia ixx=".0010" ixy="0.0" ixz="0.0" iyy=".0010" iyz="0.0" izz=".0010"/>
    </inertial>
    <visual>
      <geometry>
        <mesh filename="package://r2_description/meshes/Left_Thumb_Carp.dae"/>
      </geometry>
      <origin rpy="-1.57 0 0" xyz="-0.01 0.0 0.0"/>
    </visual>
    <collision>
      <geometry>
        <mesh filename="package://r2_description/meshes/Left_Thumb_Carp.dae" scale="0.9 0.9 0.9"/>
      </geometry>
      <origin rpy="-1.57 0 0" xyz="-0.01 0.0 0.0"/>
    </collision>
  </link>
  <link name="right_thumb_medial_prime">
    <inertial>
      <mass value=".05"/>
      <inertia ixx=".0010" ixy="0.0" ixz="0.0" iyy=".0010" iyz="0.0" izz=".0010"/>
    </inertial>
    <visual>
      <geometry>
        <mesh filename="package://r2_description/meshes/Right_Thumb_MtCar.dae"/>
      </geometry>
      <origin rpy="-1.57 -1.57 0 " xyz="-0.0 0 0.0"/>
    </visual>
    <collision>
      <geometry>
        <mesh filename="package://r2_description/meshes/Right_Thumb_MtCar.dae" scale="0.9 0.9 0.9"/>
      </geometry>
      <origin rpy="-1.57 -1.57 0 " xyz="-0.0 0 0.0"/>
    </collision>
  </link>
  <link name="right_thumb_medial">
    <inertial>
      <mass value=".05"/>
      <inertia ixx=".0010" ixy="0.0" ixz="0.0" iyy=".0010" iyz="0.0" izz=".0010"/>
    </inertial>
    <visual>
      <geometry>
        <mesh filename="package://r2_description/meshes/Thumb_Proximal.dae"/>
      </geometry>
      <origin rpy="3.14 0 1.57" xyz="0.0 0.0 0.0"/>
    </visual>
    <collision>
      <geometry>
        <mesh filename="package://r2_description/meshes/Thumb_Proximal.dae"/>
      </geometry>
      <origin rpy="3.14 0 1.57" xyz="0.0 0.0 0.0"/>
    </collision>
  </link>
  <link name="right_thumb_distal">
    <inertial>
      <mass value=".05"/>
      <inertia ixx=".0010" ixy="0.0" ixz="0.0" iyy=".0010" iyz="0.0" izz=".0010"/>
    </inertial>
    <visual>
      <geometry>
        <mesh filename="package://r2_description/meshes/Thumb_Dist.dae"/>
      </geometry>
      <origin rpy="3.14 3.14 0" xyz="0.0 0.0 0.0"/>
    </visual>
    <collision>
      <geometry>
        <mesh filename="package://r2_description/meshes/Thumb_Dist.dae"/>
      </geometry>
      <origin rpy="3.14 3.14 0" xyz="0.0 0.0 0.0"/>
    </collision>
  </link>
  <link name="right_thumb_tip">
    <inertial>
      <mass value=".05"/>
      <inertia ixx=".0010" ixy="0.0" ixz="0.0" iyy=".0010" iyz="0.0" izz=".0010"/>
    </inertial>
  </link>
  <link name="right_index_base">
    <inertial>
      <mass value=".05"/>
      <inertia ixx=".0010" ixy="0.0" ixz="0.0" iyy=".0010" iyz="0.0" izz=".0010"/>
    </inertial>
  </link>
  <link name="right_index_proximal">
    <inertial>
      <mass value=".05"/>
      <inertia ixx=".0010" ixy="0.0" ixz="0.0" iyy=".0010" iyz="0.0" izz=".0010"/>
    </inertial>
    <visual>
      <geometry>
        <mesh filename="package://r2_description/meshes/Finger_Proximal.dae"/>
      </geometry>
      <origin rpy="0 0 1.57" xyz="0.0 0.0 0.0"/>
    </visual>
    <collision>
      <geometry>
        <mesh filename="package://r2_description/meshes/Finger_Proximal.dae"/>
      </geometry>
      <origin rpy="0 0 1.57" xyz="0.0 0.0 0.0"/>
    </collision>
  </link>
  <link name="right_index_medial">
    <inertial>
      <mass value=".05"/>
      <inertia ixx=".0010" ixy="0.0" ixz="0.0" iyy=".0010" iyz="0.0" izz=".0010"/>
    </inertial>
    <visual>
      <geometry>
        <mesh filename="package://r2_description/meshes/Finger_Mid.dae"/>
      </geometry>
      <origin rpy="3.14 0 1.57" xyz="0.0 0.0 0.0"/>
    </visual>
    <collision>
      <geometry>
        <mesh filename="package://r2_description/meshes/Finger_Mid.dae"/>
      </geometry>
      <origin rpy="3.14 0 1.57" xyz="0.0 0.0 0.0"/>
    </collision>
  </link>
  <link name="right_index_distal">
    <inertial>
      <mass value=".05"/>
      <inertia ixx=".0010" ixy="0.0" ixz="0.0" iyy=".0010" iyz="0.0" izz=".0010"/>
    </inertial>
    <visual>
      <geometry>
        <mesh filename="package://r2_description/meshes/Finger_Dist.dae"/>
      </geometry>
      <origin rpy="0 -1.57 0" xyz="0.0 0.0 0.0"/>
    </visual>
    <collision>
      <geometry>
        <mesh filename="package://r2_description/meshes/Finger_Dist.dae"/>
      </geometry>
      <origin rpy="0 -1.57 0" xyz="0.0 0.0 0.0"/>
    </collision>
  </link>
  <link name="right_index_tip">
    <inertial>
      <mass value=".05"/>
      <inertia ixx=".0010" ixy="0.0" ixz="0.0" iyy=".0010" iyz="0.0" izz=".0010"/>
    </inertial>
  </link>
  <link name="right_middle_base">
    <inertial>
      <mass value=".0010"/>
      <inertia ixx=".0010" ixy="0.0" ixz="0.0" iyy=".0010" iyz="0.0" izz=".0010"/>
    </inertial>
  </link>
  <link name="right_middle_proximal">
    <inertial>
      <mass value=".05"/>
      <inertia ixx=".0010" ixy="0.0" ixz="0.0" iyy=".0010" iyz="0.0" izz=".0010"/>
    </inertial>
    <visual>
      <geometry>
        <mesh filename="package://r2_description/meshes/Finger_Proximal.dae"/>
      </geometry>
      <origin rpy="0 0 1.57" xyz="0.0 0.0 0.0"/>
    </visual>
    <collision>
      <geometry>
        <mesh filename="package://r2_description/meshes/Finger_Proximal.dae" scale="0.9 0.9 0.9"/>
      </geometry>
      <origin rpy="0 0 1.57" xyz="0.0 0.0 0.0"/>
    </collision>
  </link>
  <link name="right_middle_medial">
    <inertial>
      <mass value=".05"/>
      <inertia ixx=".0010" ixy="0.0" ixz="0.0" iyy=".0010" iyz="0.0" izz=".0010"/>
    </inertial>
    <visual>
      <geometry>
        <mesh filename="package://r2_description/meshes/Finger_Mid.dae"/>
      </geometry>
      <origin rpy="3.14 0 1.57" xyz="0.0 0.0 0.0"/>
    </visual>
    <collision>
      <geometry>
        <mesh filename="package://r2_description/meshes/Finger_Mid.dae" scale="0.9 0.9 0.9"/>
      </geometry>
      <origin rpy="3.14 0 1.57" xyz="0.0 0.0 0.0"/>
    </collision>
  </link>
  <link name="right_middle_distal">
    <inertial>
      <mass value=".05"/>
      <inertia ixx=".0010" ixy="0.0" ixz="0.0" iyy=".0010" iyz="0.0" izz=".0010"/>
    </inertial>
    <visual>
      <geometry>
        <mesh filename="package://r2_description/meshes/Finger_Dist.dae"/>
      </geometry>
      <origin rpy="0 -1.57 0" xyz="0.0 0.0 0.0"/>
    </visual>
    <collision>
      <geometry>
        <mesh filename="package://r2_description/meshes/Finger_Dist.dae" scale="0.9 0.9 0.9"/>
      </geometry>
      <origin rpy="0 -1.57 0" xyz="0.0 0.0 0.0"/>
    </collision>
  </link>
  <link name="right_middle_tip">
    <inertial>
      <mass value=".05"/>
      <inertia ixx=".0010" ixy="0.0" ixz="0.0" iyy=".0010" iyz="0.0" izz=".0010"/>
    </inertial>
  </link>
  <link name="right_ring_proximal">
    <inertial>
      <mass value=".05"/>
      <inertia ixx=".0010" ixy="0.0" ixz="0.0" iyy=".0010" iyz="0.0" izz=".0010"/>
    </inertial>
    <visual>
      <geometry>
        <mesh filename="package://r2_description/meshes/Finger_Proximal.dae"/>
      </geometry>
      <origin rpy="0 0 1.57" xyz="0.0 0.0 0.0"/>
    </visual>
    <collision>
      <geometry>
        <mesh filename="package://r2_description/meshes/Finger_Proximal.dae" scale="0.9 0.9 0.9"/>
      </geometry>
      <origin rpy="0 0 1.57" xyz="0.0 0.0 0.0"/>
    </collision>
  </link>
  <link name="right_ring_medial">
    <inertial>
      <mass value=".05"/>
      <inertia ixx=".0010" ixy="0.0" ixz="0.0" iyy=".0010" iyz="0.0" izz=".0010"/>
    </inertial>
    <visual>
      <geometry>
        <mesh filename="package://r2_description/meshes/Finger_Mid.dae"/>
      </geometry>
      <origin rpy="3.14 0 1.57" xyz="0.0 0.0 0.0"/>
    </visual>
    <collision>
      <geometry>
        <mesh filename="package://r2_description/meshes/Finger_Mid.dae" scale="0.9 0.9 0.9"/>
      </geometry>
      <origin rpy="3.14 0 1.57" xyz="0.0 0.0 0.0"/>
    </collision>
  </link>
  <link name="right_ring_distal">
    <inertial>
      <mass value=".05"/>
      <inertia ixx=".0010" ixy="0.0" ixz="0.0" iyy=".0010" iyz="0.0" izz=".0010"/>
    </inertial>
    <visual>
      <geometry>
        <mesh filename="package://r2_description/meshes/Finger_Dist.dae"/>
      </geometry>
      <origin rpy="0 -1.57 0" xyz="0.0 0.0 0.0"/>
    </visual>
    <collision>
      <geometry>
        <mesh filename="package://r2_description/meshes/Finger_Dist.dae" scale="0.9 0.9 0.9"/>
      </geometry>
      <origin rpy="0 -1.57 0" xyz="0.0 0.0 0.0"/>
    </collision>
  </link>
  <link name="right_ring_tip">
    <inertial>
      <mass value=".05"/>
      <inertia ixx=".0010" ixy="0.0" ixz="0.0" iyy=".0010" iyz="0.0" izz=".0010"/>
    </inertial>
  </link>
  <link name="right_little_proximal">
    <inertial>
      <mass value=".05"/>
      <inertia ixx=".0010" ixy="0.0" ixz="0.0" iyy=".0010" iyz="0.0" izz=".0010"/>
    </inertial>
    <visual>
      <geometry>
        <mesh filename="package://r2_description/meshes/Finger_Proximal.dae"/>
      </geometry>
      <origin rpy="0 0 1.57" xyz="0.0 0.0 0.0"/>
    </visual>
    <collision>
      <geometry>
        <mesh filename="package://r2_description/meshes/Finger_Proximal.dae" scale="0.9 0.9 0.9"/>
      </geometry>
      <origin rpy="0 0 1.57" xyz="0.0 0.0 0.0"/>
    </collision>
  </link>
  <link name="right_little_medial">
    <inertial>
      <mass value=".05"/>
      <inertia ixx=".0010" ixy="0.0" ixz="0.0" iyy=".0010" iyz="0.0" izz=".0010"/>
    </inertial>
    <visual>
      <geometry>
        <mesh filename="package://r2_description/meshes/Finger_Mid.dae"/>
      </geometry>
      <origin rpy="3.14 0 1.57" xyz="0.0 0.0 0.0"/>
    </visual>
    <collision>
      <geometry>
        <mesh filename="package://r2_description/meshes/Finger_Mid.dae" scale="0.9 0.9 0.9"/>
      </geometry>
      <origin rpy="3.14 0 1.57" xyz="0.0 0.0 0.0"/>
    </collision>
  </link>
  <link name="right_little_distal">
    <inertial>
      <mass value=".05"/>
      <inertia ixx=".0010" ixy="0.0" ixz="0.0" iyy=".0010" iyz="0.0" izz=".0010"/>
    </inertial>
    <visual>
      <geometry>
        <mesh filename="package://r2_description/meshes/Finger_Dist.dae"/>
      </geometry>
      <origin rpy="0 -1.57 0" xyz="0.0 0.0 0.0"/>
    </visual>
    <collision>
      <geometry>
        <mesh filename="package://r2_description/meshes/Finger_Dist.dae" scale="0.9 0.9 0.9"/>
      </geometry>
      <origin rpy="0 -1.57 0" xyz="0.0 0.0 0.0"/>
    </collision>
  </link>
  <link name="right_little_tip">
    <inertial>
      <mass value=".05"/>
      <inertia ixx=".0010" ixy="0.0" ixz="0.0" iyy=".0010" iyz="0.0" izz=".0010"/>
    </inertial>
  </link>
  <joint name="right_thumb/j0" type="revolute">
    <parent link="right_wrist_yaw"/>
    <child link="right_thumb_base"/>
    <origin rpy=" 1.57079632679 0.174532791018 -1.30899687745 " xyz="0.03302 -0.03048 0.00635 "/>
    <axis xyz="0 0 1"/>
    <limit effort="10000000.0" lower="0.0" upper="1.2217" velocity="1000"/>
    <dynamics damping="0.1"/>
  </joint>
  <joint name="right_thumb/j1" type="fixed">
    <parent link="right_thumb_base"/>
    <child link="right_thumb_proximal"/>
    <origin rpy=" -1.570796 -0.0 0.0 " xyz=" 0.011938 0.0 0.0 "/>
    <dynamics damping="0.1"/>
  </joint>
  <joint name="right_thumb/j2" type="revolute">
    <parent link="right_thumb_proximal"/>
    <child link="right_thumb_medial_prime"/>
    <origin rpy=" 0.0 -0.0 0.0 " xyz=" 0.0 0.0 0.0 "/>
    <axis xyz="0 0 1"/>
    <limit effort="10000000.0" lower="0.0" upper="1.3963" velocity="1000"/>
    <dynamics damping="0.1"/>
  </joint>
  <joint name="right_thumb/j3" type="revolute">
    <parent link="right_thumb_medial_prime"/>
    <child link="right_thumb_medial"/>
    <origin rpy=" 0.698132284627 -0.0 0.0 " xyz=" 0.030734 -0.001905 -0.00254 "/>
    <axis xyz="0 0 1"/>
    <limit effort="10000000.0" lower="0.0" upper="1.2217" velocity="1000"/>
    <dynamics damping="0.1"/>
  </joint>
  <joint name="right_thumb/j4" type="revolute">
    <parent link="right_thumb_medial"/>
    <child link="right_thumb_distal"/>
    <origin rpy=" 0.0 -0.0 0.0 " xyz=" 0.03937 0.0 0.0 "/>
    <axis xyz="0 0 1"/>
    <limit effort="10000000.0" lower="-0.5236" upper="1.57" velocity="1000"/>
    <dynamics damping="0.1"/>
  </joint>
  <joint name="right_thumb/j5" type="fixed">
    <parent link="right_thumb_distal"/>
    <child link="right_thumb_tip"/>
    <origin rpy=" 0.0 -0.0 0.0 " xyz=" 0.03302 0.0 0.0 "/>
    <dynamics damping="0.1"/>
  </joint>
  <joint name="right_index/j0" type="revolute">
    <parent link="right_wrist_yaw"/>
    <child link="right_index_base"/>
    <origin rpy=" 0.0 -0.0 -0.122172725275  " xyz=" 0.0994646728 -0.0271119346 -0.0161544 "/>
    <axis xyz="0 0 1"/>
    <limit effort="10000000.0" lower="-0.3491" upper="0.3491" velocity="1000"/>
    <dynamics damping="0.1"/>
  </joint>
  <joint name="right_index/j1" type="revolute">
    <parent link="right_index_base"/>
    <child link="right_index_proximal"/>
    <origin rpy=" 1.570796 -0.0 0.0 " xyz=" 0.009652 0.0 0.0 "/>
    <axis xyz="0 0 1"/>
    <limit effort="10000000.0" lower="0.0" upper="1.57" velocity="1000"/>
    <dynamics damping="0.1"/>
  </joint>
  <joint name="right_index/j2" type="revolute">
    <parent link="right_index_proximal"/>
    <child link="right_index_medial"/>
    <origin rpy=" 0.0 -0.0 0.0 " xyz=" 0.04445 0.0 0.0 "/>
    <axis xyz="0 0 1"/>
    <limit effort="10000000.0" lower="0.0" upper="1.57" velocity="1000"/>
    <dynamics damping="0.1"/>
  </joint>
  <joint name="right_index/j3" type="revolute">
    <parent link="right_index_medial"/>
    <child link="right_index_distal"/>
    <origin rpy=" 0.0 -0.0 0.0 " xyz=" 0.03048 0.0 0.0 "/>
    <axis xyz="0 0 1"/>
    <limit effort="10000000.0" lower="0.0" upper="1.57" velocity="1000"/>
    <dynamics damping="0.1"/>
  </joint>
  <joint name="right_index/j4" type="fixed">
    <parent link="right_index_distal"/>
    <child link="right_index_tip"/>
    <origin rpy=" 0.0 -0.0 0.0 " xyz=" 0.024638 0.0 0.0 "/>
    <dynamics damping="0.1"/>
  </joint>
  <joint name="right_middle/j0" type="revolute">
    <parent link="right_wrist_yaw"/>
    <child link="right_middle_base"/>
    <origin rpy=" 0.0 -0.0 0.0 " xyz="0.10646537 -0.00254 -0.0161544 "/>
    <axis xyz="0 0 1"/>
    <limit effort="10000000.0" lower="-0.3491" upper="0.3491" velocity="1000"/>
    <dynamics damping="0.1"/>
  </joint>
  <joint name="right_middle/j1" type="revolute">
    <parent link="right_middle_base"/>
    <child link="right_middle_proximal"/>
    <origin rpy=" 1.570796 -0.0 0.0 " xyz=" 0.009652 0.0 0.0 "/>
    <axis xyz="0 0 1"/>
    <limit effort="10000000.0" lower="0.0" upper="1.57" velocity="1000"/>
    <dynamics damping="0.1"/>
  </joint>
  <joint name="right_middle/j2" type="revolute">
    <parent link="right_middle_proximal"/>
    <child link="right_middle_medial"/>
    <origin rpy=" 0.0 -0.0 0.0 " xyz=" 0.04445 0.0 0.0 "/>
    <axis xyz="0 0 1"/>
    <limit effort="10000000.0" lower="0.0" upper="1.57" velocity="1000"/>
    <dynamics damping="0.1"/>
  </joint>
  <joint name="right_middle/j3" type="revolute">
    <parent link="right_middle_medial"/>
    <child link="right_middle_distal"/>
    <origin rpy=" 0.0 -0.0 0.0 " xyz=" 0.03048 0.0 0.0 "/>
    <axis xyz="0 0 1"/>
    <limit effort="10000000.0" lower="0.0" upper="1.57" velocity="1000"/>
    <dynamics damping="0.1"/>
  </joint>
  <joint name="right_middle/j4" type="fixed">
    <parent link="right_middle_distal"/>
    <child link="right_middle_tip"/>
    <origin rpy=" 0.0 -0.0 0.0 " xyz=" 0.024638 0.0 0.0 "/>
    <dynamics damping="0.1"/>
  </joint>
  <joint name="right_ring/j0" type="revolute">
    <parent link="right_wrist_yaw"/>
    <child link="right_ring_proximal"/>
    <origin rpy=" 1.57079632679 -0.0 0.122172725275  " xyz=" 0.1084539614 0.019792569 -0.012319 "/>
    <axis xyz="0 0 1"/>
    <limit effort="10000000.0" lower="0" upper="2.9671" velocity="1000"/>
    <dynamics damping="0.1"/>
  </joint>
  <joint name="right_ring/j1" type="revolute">
    <parent link="right_ring_proximal"/>
    <child link="right_ring_medial"/>
    <origin rpy=" 0.0 -0.0 0.0 " xyz=" 0.04445 0.0 0.0 "/>
    <axis xyz="0 0 1"/>
    <limit effort="10000000.0" lower="0" upper="2.9671" velocity="1000"/>
    <dynamics damping="0.1"/>
  </joint>
  <joint name="right_ring/j2" type="revolute">
    <parent link="right_ring_medial"/>
    <child link="right_ring_distal"/>
    <origin rpy=" 0.0 -0.0 0.0 " xyz=" 0.03048 0.0 0.0 "/>
    <axis xyz="0 0 1"/>
    <limit effort="10000000.0" lower="0" upper="2.9671" velocity="1000"/>
    <dynamics damping="0.1"/>
  </joint>
  <joint name="right_ring/j3" type="fixed">
    <parent link="right_ring_distal"/>
    <child link="right_ring_tip"/>
    <origin rpy=" 0.0 -0.0 0.0 " xyz=" 0.024638 0.0 0.0 "/>
    <dynamics damping="0.1"/>
  </joint>
  <joint name="right_little/j0" type="revolute">
    <parent link="right_wrist_yaw"/>
    <child link="right_little_proximal"/>
    <origin rpy=" 1.53588943985 -0.0872667473393 0.17453258148  " xyz=" 0.094635701 0.0403792436 -0.0060878212 "/>
    <axis xyz="0 0 1"/>
    <limit effort="10000000.0" lower="0" upper="2.9671" velocity="1000"/>
    <dynamics damping="0.1"/>
  </joint>
  <joint name="right_little/j1" type="revolute">
    <parent link="right_little_proximal"/>
    <child link="right_little_medial"/>
    <origin rpy=" 0.0 -0.0 0.0 " xyz=" 0.04445 0.0 0.0 "/>
    <axis xyz="0 0 1"/>
    <limit effort="10000000.0" lower="0" upper="2.9671" velocity="1000"/>
    <dynamics damping="0.1"/>
  </joint>
  <joint name="right_little/j2" type="revolute">
    <parent link="right_little_medial"/>
    <child link="right_little_distal"/>
    <origin rpy=" 0.0 -0.0 0.0 " xyz=" 0.03048 0.0 0.0 "/>
    <axis xyz="0 0 1"/>
    <limit effort="10000000.0" lower="0" upper="2.9671" velocity="1000"/>
    <dynamics damping="0.1"/>
  </joint>
  <joint name="right_little/j3" type="fixed">
    <parent link="right_little_distal"/>
    <child link="right_little_tip"/>
    <origin rpy=" 0.0 -0.0 0.0 " xyz=" 0.024638 0.0 0.0 "/>
    <dynamics damping="0.1"/>
  </joint>
  <gazebo reference="waist_center">
    <selfCollide>false</selfCollide>
    <static>false</static>
    <turnGravityOff>false</turnGravityOff>
  </gazebo>
  <gazebo reference="waist/j0">
    <stopKd value="1.0"/>
    <stopKp value="1000000.0"/>
  </gazebo>
  <gazebo reference="left_shoulder_roll">
    <selfCollide>false</selfCollide>
    <static>false</static>
    <turnGravityOff>false</turnGravityOff>
  </gazebo>
  <gazebo reference="left_shoulder_pitch">
    <selfCollide>false</selfCollide>
    <static>false</static>
    <turnGravityOff>false</turnGravityOff>
  </gazebo>
  <gazebo reference="left_upper_arm">
    <selfCollide>false</selfCollide>
    <static>false</static>
    <turnGravityOff>false</turnGravityOff>
  </gazebo>
  <gazebo reference="left_elbow">
    <selfCollide>false</selfCollide>
    <static>false</static>
    <turnGravityOff>false</turnGravityOff>
  </gazebo>
  <gazebo reference="left_lower_arm">
    <selfCollide>false</selfCollide>
    <static>false</static>
    <turnGravityOff>false</turnGravityOff>
  </gazebo>
  <gazebo reference="left_wrist_pitch">
    <selfCollide>false</selfCollide>
    <static>false</static>
    <turnGravityOff>false</turnGravityOff>
  </gazebo>
  <gazebo reference="left_wrist_yaw">
    <selfCollide>false</selfCollide>
    <static>false</static>
    <turnGravityOff>false</turnGravityOff>
  </gazebo>
  <gazebo reference="left_palm">
    <selfCollide>false</selfCollide>
    <static>false</static>
    <turnGravityOff>false</turnGravityOff>
  </gazebo>
  <gazebo reference="left/j0">
    <stopKd value="1.0"/>
    <stopKp value="1000000.0"/>
  </gazebo>
  <gazebo reference="left/j1">
    <stopKd value="1.0"/>
    <stopKp value="1000000.0"/>
  </gazebo>
  <gazebo reference="left/j2">
    <stopKd value="1.0"/>
    <stopKp value="1000000.0"/>
  </gazebo>
  <gazebo reference="left/j3">
    <stopKd value="1.0"/>
    <stopKp value="1000000.0"/>
  </gazebo>
  <gazebo reference="left/j4">
    <stopKd value="1.0"/>
    <stopKp value="1000000.0"/>
  </gazebo>
  <gazebo reference="left/j5">
    <stopKd value="1.0"/>
    <stopKp value="1000000.0"/>
  </gazebo>
  <gazebo reference="left/j6">
    <stopKd value="1.0"/>
    <stopKp value="1000000.0"/>
  </gazebo>
  <gazebo reference="left_thumb_base">
    <selfCollide>false</selfCollide>
    <static>false</static>
    <turnGravityOff>false</turnGravityOff>
  </gazebo>
  <gazebo reference="left_thumb_medial_prime">
    <selfCollide>false</selfCollide>
    <static>false</static>
    <turnGravityOff>false</turnGravityOff>
  </gazebo>
  <gazebo reference="left_thumb_medial">
    <selfCollide>false</selfCollide>
    <static>false</static>
    <turnGravityOff>false</turnGravityOff>
  </gazebo>
  <gazebo reference="left_thumb_distal">
    <selfCollide>false</selfCollide>
    <static>false</static>
    <turnGravityOff>false</turnGravityOff>
  </gazebo>
  <gazebo reference="left_index_base">
    <selfCollide>false</selfCollide>
    <static>false</static>
    <turnGravityOff>false</turnGravityOff>
  </gazebo>
  <gazebo reference="left_index_proximal">
    <selfCollide>false</selfCollide>
    <static>false</static>
    <turnGravityOff>false</turnGravityOff>
  </gazebo>
  <gazebo reference="left_index_medial">
    <selfCollide>false</selfCollide>
    <static>false</static>
    <turnGravityOff>false</turnGravityOff>
  </gazebo>
  <gazebo reference="left_index_distal">
    <selfCollide>false</selfCollide>
    <static>false</static>
    <turnGravityOff>false</turnGravityOff>
  </gazebo>
  <gazebo reference="left_middle_base">
    <selfCollide>false</selfCollide>
    <static>false</static>
    <turnGravityOff>false</turnGravityOff>
  </gazebo>
  <gazebo reference="left_middle_proximal">
    <selfCollide>false</selfCollide>
    <static>false</static>
    <turnGravityOff>false</turnGravityOff>
  </gazebo>
  <gazebo reference="left_middle_medial">
    <selfCollide>false</selfCollide>
    <static>false</static>
    <turnGravityOff>false</turnGravityOff>
  </gazebo>
  <gazebo reference="left_middle_distal">
    <selfCollide>false</selfCollide>
    <static>false</static>
    <turnGravityOff>false</turnGravityOff>
  </gazebo>
  <gazebo reference="left_ring_proximal">
    <selfCollide>false</selfCollide>
    <static>false</static>
    <turnGravityOff>false</turnGravityOff>
  </gazebo>
  <gazebo reference="left_ring_medial">
    <selfCollide>false</selfCollide>
    <static>false</static>
    <turnGravityOff>false</turnGravityOff>
  </gazebo>
  <gazebo reference="left_ring_distal">
    <selfCollide>false</selfCollide>
    <static>false</static>
    <turnGravityOff>false</turnGravityOff>
  </gazebo>
  <gazebo reference="left_little_proximal">
    <selfCollide>false</selfCollide>
    <static>false</static>
    <turnGravityOff>false</turnGravityOff>
  </gazebo>
  <gazebo reference="left_little_medial">
    <selfCollide>false</selfCollide>
    <static>false</static>
    <turnGravityOff>false</turnGravityOff>
  </gazebo>
  <gazebo reference="left_little_distal">
    <selfCollide>false</selfCollide>
    <static>false</static>
    <turnGravityOff>false</turnGravityOff>
  </gazebo>
  <gazebo reference="right_shoulder_roll">
    <selfCollide>false</selfCollide>
    <static>false</static>
    <turnGravityOff>false</turnGravityOff>
  </gazebo>
  <gazebo reference="right_shoulder_pitch">
    <selfCollide>false</selfCollide>
    <static>false</static>
    <turnGravityOff>false</turnGravityOff>
  </gazebo>
  <gazebo reference="right_upper_arm">
    <selfCollide>false</selfCollide>
    <static>false</static>
    <turnGravityOff>false</turnGravityOff>
  </gazebo>
  <gazebo reference="right_elbow">
    <selfCollide>false</selfCollide>
    <static>false</static>
    <turnGravityOff>false</turnGravityOff>
  </gazebo>
  <gazebo reference="right_lower_arm">
    <selfCollide>false</selfCollide>
    <static>false</static>
    <turnGravityOff>false</turnGravityOff>
  </gazebo>
  <gazebo reference="right_wrist_pitch">
    <selfCollide>false</selfCollide>
    <static>false</static>
    <turnGravityOff>false</turnGravityOff>
  </gazebo>
  <gazebo reference="right_wrist_yaw">
    <selfCollide>false</selfCollide>
    <static>false</static>
    <turnGravityOff>false</turnGravityOff>
  </gazebo>
  <gazebo reference="right_palm">
    <selfCollide>false</selfCollide>
    <static>false</static>
    <turnGravityOff>false</turnGravityOff>
  </gazebo>
  <gazebo reference="right/j0">
    <stopKd value="1.0"/>
    <stopKp value="1000000.0"/>
  </gazebo>
  <gazebo reference="right/j1">
    <stopKd value="1.0"/>
    <stopKp value="1000000.0"/>
  </gazebo>
  <gazebo reference="right/j2">
    <stopKd value="1.0"/>
    <stopKp value="1000000.0"/>
  </gazebo>
  <gazebo reference="right/j3">
    <stopKd value="1.0"/>
    <stopKp value="1000000.0"/>
  </gazebo>
  <gazebo reference="right/j4">
    <stopKd value="1.0"/>
    <stopKp value="1000000.0"/>
  </gazebo>
  <gazebo reference="right/j5">
    <stopKd value="1.0"/>
    <stopKp value="1000000.0"/>
  </gazebo>
  <gazebo reference="right/j6">
    <stopKd value="1.0"/>
    <stopKp value="1000000.0"/>
  </gazebo>
  <gazebo reference="right_thumb_base">
    <selfCollide>false</selfCollide>
    <static>false</static>
    <turnGravityOff>false</turnGravityOff>
  </gazebo>
  <gazebo reference="right_thumb_medial_prime">
    <selfCollide>false</selfCollide>
    <static>false</static>
    <turnGravityOff>false</turnGravityOff>
  </gazebo>
  <gazebo reference="right_thumb_medial">
    <selfCollide>false</selfCollide>
    <static>false</static>
    <turnGravityOff>false</turnGravityOff>
  </gazebo>
  <gazebo reference="right_thumb_distal">
    <selfCollide>false</selfCollide>
    <static>false</static>
    <turnGravityOff>false</turnGravityOff>
  </gazebo>
  <gazebo reference="right_index_base">
    <selfCollide>false</selfCollide>
    <static>false</static>
    <turnGravityOff>false</turnGravityOff>
  </gazebo>
  <gazebo reference="right_index_proximal">
    <selfCollide>false</selfCollide>
    <static>false</static>
    <turnGravityOff>false</turnGravityOff>
  </gazebo>
  <gazebo reference="right_index_medial">
    <selfCollide>false</selfCollide>
    <static>false</static>
    <turnGravityOff>false</turnGravityOff>
  </gazebo>
  <gazebo reference="right_index_distal">
    <selfCollide>false</selfCollide>
    <static>false</static>
    <turnGravityOff>false</turnGravityOff>
  </gazebo>
  <gazebo reference="right_middle_base">
    <selfCollide>false</selfCollide>
    <static>false</static>
    <turnGravityOff>false</turnGravityOff>
  </gazebo>
  <gazebo reference="right_middle_proximal">
    <selfCollide>false</selfCollide>
    <static>false</static>
    <turnGravityOff>false</turnGravityOff>
  </gazebo>
  <gazebo reference="right_middle_medial">
    <selfCollide>false</selfCollide>
    <static>false</static>
    <turnGravityOff>false</turnGravityOff>
  </gazebo>
  <gazebo reference="right_middle_distal">
    <selfCollide>false</selfCollide>
    <static>false</static>
    <turnGravityOff>false</turnGravityOff>
  </gazebo>
  <gazebo reference="right_ring_proximal">
    <selfCollide>false</selfCollide>
    <static>false</static>
    <turnGravityOff>false</turnGravityOff>
  </gazebo>
  <gazebo reference="right_ring_medial">
    <selfCollide>false</selfCollide>
    <static>false</static>
    <turnGravityOff>false</turnGravityOff>
  </gazebo>
  <gazebo reference="right_ring_distal">
    <selfCollide>false</selfCollide>
    <static>false</static>
    <turnGravityOff>false</turnGravityOff>
  </gazebo>
  <gazebo reference="right_little_proximal">
    <selfCollide>false</selfCollide>
    <static>false</static>
    <turnGravityOff>false</turnGravityOff>
  </gazebo>
  <gazebo reference="right_little_medial">
    <selfCollide>false</selfCollide>
    <static>false</static>
    <turnGravityOff>false</turnGravityOff>
  </gazebo>
  <gazebo reference="right_little_distal">
    <selfCollide>false</selfCollide>
    <static>false</static>
    <turnGravityOff>false</turnGravityOff>
  </gazebo>
  <gazebo reference="neck_base">
    <selfCollide>false</selfCollide>
    <static>false</static>
    <turnGravityOff>false</turnGravityOff>
  </gazebo>
  <gazebo reference="neck/j0">
    <stopKd value="1.0"/>
    <stopKp value="1000000.0"/>
  </gazebo>
  <gazebo reference="neck_lower_pitch">
    <selfCollide>false</selfCollide>
    <static>false</static>
    <turnGravityOff>false</turnGravityOff>
  </gazebo>
  <gazebo reference="neck/j0">
    <stopKd value="1.0"/>
    <stopKp value="1000000.0"/>
  </gazebo>
  <gazebo reference="neck_roll">
    <selfCollide>false</selfCollide>
    <static>false</static>
    <turnGravityOff>false</turnGravityOff>
  </gazebo>
  <gazebo reference="neck/j0">
    <stopKd value="1.0"/>
    <stopKp value="1000000.0"/>
  </gazebo>
  <transmission name="waist_j0_trans" type="pr2_mechanism_model/SimpleTransmission">
    <actuator name="waist_j0_motor"/>
    <joint name="waist/j0"/>
    <mechanicalReduction>0.00625</mechanicalReduction>
    <motorTorqueConstant>0.1</motorTorqueConstant>
  </transmission>
  <transmission name="left_j0_trans" type="pr2_mechanism_model/SimpleTransmission">
    <actuator name="left_j0_motor"/>
    <joint name="left/j0"/>
    <mechanicalReduction>160</mechanicalReduction>
    <motorTorqueConstant>0.305</motorTorqueConstant>
  </transmission>
  <transmission name="left_j1_trans" type="pr2_mechanism_model/SimpleTransmission">
    <actuator name="left_j1_motor"/>
    <joint name="left/j1"/>
    <mechanicalReduction>160</mechanicalReduction>
    <motorTorqueConstant>0.305</motorTorqueConstant>
  </transmission>
  <transmission name="left_j2_trans" type="pr2_mechanism_model/SimpleTransmission">
    <actuator name="left_j2_motor"/>
    <joint name="left/j2"/>
    <mechanicalReduction>160</mechanicalReduction>
    <motorTorqueConstant>0.159</motorTorqueConstant>
  </transmission>
  <transmission name="left_j3_trans" type="pr2_mechanism_model/SimpleTransmission">
    <actuator name="left_j3_motor"/>
    <joint name="left/j3"/>
    <mechanicalReduction>160</mechanicalReduction>
    <motorTorqueConstant>0.159</motorTorqueConstant>
  </transmission>
  <transmission name="left_j4_trans" type="pr2_mechanism_model/SimpleTransmission">
    <actuator name="left_j4_motor"/>
    <joint name="left/j4"/>
    <mechanicalReduction>160</mechanicalReduction>
    <motorTorqueConstant>0.056</motorTorqueConstant>
  </transmission>
  <transmission name="left_j5_trans" type="pr2_mechanism_model/SimpleTransmission">
    <actuator name="left_j5_motor"/>
    <joint name="left/j5"/>
    <mechanicalReduction>1</mechanicalReduction>
    <motorTorqueConstant>1</motorTorqueConstant>
  </transmission>
  <transmission name="left_j6_trans" type="pr2_mechanism_model/SimpleTransmission">
    <actuator name="left_j6_motor"/>
    <joint name="left/j6"/>
    <mechanicalReduction>1</mechanicalReduction>
    <motorTorqueConstant>1</motorTorqueConstant>
  </transmission>
  <transmission name="left_thumb_j0_trans" type="pr2_mechanism_model/SimpleTransmission">
    <actuator name="left_thumb_j0_motor"/>
    <joint name="left_thumb/j0"/>
    <mechanicalReduction>1</mechanicalReduction>
    <motorTorqueConstant>1</motorTorqueConstant>
  </transmission>
  <transmission name="left_thumb_j2_trans" type="pr2_mechanism_model/SimpleTransmission">
    <actuator name="left_thumb_j2_motor"/>
    <joint name="left_thumb/j2"/>
    <mechanicalReduction>1</mechanicalReduction>
    <motorTorqueConstant>1</motorTorqueConstant>
  </transmission>
  <transmission name="left_thumb_j3_trans" type="pr2_mechanism_model/SimpleTransmission">
    <actuator name="left_thumb_j3_motor"/>
    <joint name="left_thumb/j3"/>
    <mechanicalReduction>1</mechanicalReduction>
    <motorTorqueConstant>1</motorTorqueConstant>
  </transmission>
  <transmission name="left_thumb_j4_trans" type="pr2_mechanism_model/SimpleTransmission">
    <actuator name="left_thumb_j4_motor"/>
    <joint name="left_thumb/j4"/>
    <mechanicalReduction>1</mechanicalReduction>
    <motorTorqueConstant>1</motorTorqueConstant>
  </transmission>
  <transmission name="left_index_j0_trans" type="pr2_mechanism_model/SimpleTransmission">
    <actuator name="left_index_j0_motor"/>
    <joint name="left_index/j0"/>
    <mechanicalReduction>1</mechanicalReduction>
    <motorTorqueConstant>1</motorTorqueConstant>
  </transmission>
  <transmission name="left_index_j1_trans" type="pr2_mechanism_model/SimpleTransmission">
    <actuator name="left_index_j1_motor"/>
    <joint name="left_index/j1"/>
    <mechanicalReduction>1</mechanicalReduction>
    <motorTorqueConstant>1</motorTorqueConstant>
  </transmission>
  <transmission name="left_index_j2_trans" type="pr2_mechanism_model/SimpleTransmission">
    <actuator name="left_index_j2_motor"/>
    <joint name="left_index/j2"/>
    <mechanicalReduction>1</mechanicalReduction>
    <motorTorqueConstant>1</motorTorqueConstant>
  </transmission>
  <transmission name="left_index_j3_trans" type="pr2_mechanism_model/SimpleTransmission">
    <actuator name="left_index_j3_motor"/>
    <joint name="left_index/j3"/>
    <mechanicalReduction>1</mechanicalReduction>
    <motorTorqueConstant>1</motorTorqueConstant>
  </transmission>
  <transmission name="left_middle_j0_trans" type="pr2_mechanism_model/SimpleTransmission">
    <actuator name="left_middle_j0_motor"/>
    <joint name="left_middle/j0"/>
    <mechanicalReduction>1</mechanicalReduction>
    <motorTorqueConstant>1</motorTorqueConstant>
  </transmission>
  <transmission name="left_middle_j1_trans" type="pr2_mechanism_model/SimpleTransmission">
    <actuator name="left_middle_j1_motor"/>
    <joint name="left_middle/j1"/>
    <mechanicalReduction>1</mechanicalReduction>
    <motorTorqueConstant>1</motorTorqueConstant>
  </transmission>
  <transmission name="left_middle_j2_trans" type="pr2_mechanism_model/SimpleTransmission">
    <actuator name="left_middle_j2_motor"/>
    <joint name="left_middle/j2"/>
    <mechanicalReduction>1</mechanicalReduction>
    <motorTorqueConstant>1</motorTorqueConstant>
  </transmission>
  <transmission name="left_middle_j3_trans" type="pr2_mechanism_model/SimpleTransmission">
    <actuator name="left_middle_j3_motor"/>
    <joint name="left_middle/j3"/>
    <mechanicalReduction>1</mechanicalReduction>
    <motorTorqueConstant>1</motorTorqueConstant>
  </transmission>
  <transmission name="left_ring_j0_trans" type="pr2_mechanism_model/SimpleTransmission">
    <actuator name="left_ring_j0_motor"/>
    <joint name="left_ring/j0"/>
    <mechanicalReduction>1</mechanicalReduction>
    <motorTorqueConstant>1</motorTorqueConstant>
  </transmission>
  <transmission name="left_ring_j1_trans" type="pr2_mechanism_model/SimpleTransmission">
    <actuator name="left_ring_j1_motor"/>
    <joint name="left_ring/j1"/>
    <mechanicalReduction>1</mechanicalReduction>
    <motorTorqueConstant>1</motorTorqueConstant>
  </transmission>
  <transmission name="left_ring_j2_trans" type="pr2_mechanism_model/SimpleTransmission">
    <actuator name="left_ring_j2_motor"/>
    <joint name="left_ring/j2"/>
    <mechanicalReduction>1</mechanicalReduction>
    <motorTorqueConstant>1</motorTorqueConstant>
  </transmission>
  <transmission name="left_little_j0_trans" type="pr2_mechanism_model/SimpleTransmission">
    <actuator name="left_little_j0_motor"/>
    <joint name="left_little/j0"/>
    <mechanicalReduction>1</mechanicalReduction>
    <motorTorqueConstant>1</motorTorqueConstant>
  </transmission>
  <transmission name="left_little_j1_trans" type="pr2_mechanism_model/SimpleTransmission">
    <actuator name="left_little_j1_motor"/>
    <joint name="left_little/j1"/>
    <mechanicalReduction>1</mechanicalReduction>
    <motorTorqueConstant>1</motorTorqueConstant>
  </transmission>
  <transmission name="left_little_j2_trans" type="pr2_mechanism_model/SimpleTransmission">
    <actuator name="left_little_j2_motor"/>
    <joint name="left_little/j2"/>
    <mechanicalReduction>1</mechanicalReduction>
    <motorTorqueConstant>1</motorTorqueConstant>
  </transmission>
  <transmission name="right_j0_trans" type="pr2_mechanism_model/SimpleTransmission">
    <actuator name="right_j0_motor"/>
    <joint name="right/j0"/>
    <mechanicalReduction>160</mechanicalReduction>
    <motorTorqueConstant>0.305</motorTorqueConstant>
  </transmission>
  <transmission name="right_j1_trans" type="pr2_mechanism_model/SimpleTransmission">
    <actuator name="right_j1_motor"/>
    <joint name="right/j1"/>
    <mechanicalReduction>160</mechanicalReduction>
    <motorTorqueConstant>0.305</motorTorqueConstant>
  </transmission>
  <transmission name="right_j2_trans" type="pr2_mechanism_model/SimpleTransmission">
    <actuator name="right_j2_motor"/>
    <joint name="right/j2"/>
    <mechanicalReduction>160</mechanicalReduction>
    <motorTorqueConstant>0.159</motorTorqueConstant>
  </transmission>
  <transmission name="right_j3_trans" type="pr2_mechanism_model/SimpleTransmission">
    <actuator name="right_j3_motor"/>
    <joint name="right/j3"/>
    <mechanicalReduction>160</mechanicalReduction>
    <motorTorqueConstant>0.159</motorTorqueConstant>
  </transmission>
  <transmission name="right_j4_trans" type="pr2_mechanism_model/SimpleTransmission">
    <actuator name="right_j4_motor"/>
    <joint name="right/j4"/>
    <mechanicalReduction>160</mechanicalReduction>
    <motorTorqueConstant>0.056</motorTorqueConstant>
  </transmission>
  <transmission name="right_j5_trans" type="pr2_mechanism_model/SimpleTransmission">
    <actuator name="right_j5_motor"/>
    <joint name="right/j5"/>
    <mechanicalReduction>1</mechanicalReduction>
    <motorTorqueConstant>1</motorTorqueConstant>
  </transmission>
  <transmission name="right_j6_trans" type="pr2_mechanism_model/SimpleTransmission">
    <actuator name="right_j6_motor"/>
    <joint name="right/j6"/>
    <mechanicalReduction>1</mechanicalReduction>
    <motorTorqueConstant>1</motorTorqueConstant>
  </transmission>
  <transmission name="right_thumb_j0_trans" type="pr2_mechanism_model/SimpleTransmission">
    <actuator name="right_thumb_j0_motor"/>
    <joint name="right_thumb/j0"/>
    <mechanicalReduction>1</mechanicalReduction>
    <motorTorqueConstant>1</motorTorqueConstant>
  </transmission>
  <transmission name="right_thumb_j2_trans" type="pr2_mechanism_model/SimpleTransmission">
    <actuator name="right_thumb_j2_motor"/>
    <joint name="right_thumb/j2"/>
    <mechanicalReduction>1</mechanicalReduction>
    <motorTorqueConstant>1</motorTorqueConstant>
  </transmission>
  <transmission name="right_thumb_j3_trans" type="pr2_mechanism_model/SimpleTransmission">
    <actuator name="right_thumb_j3_motor"/>
    <joint name="right_thumb/j3"/>
    <mechanicalReduction>1</mechanicalReduction>
    <motorTorqueConstant>1</motorTorqueConstant>
  </transmission>
  <transmission name="right_thumb_j4_trans" type="pr2_mechanism_model/SimpleTransmission">
    <actuator name="right_thumb_j4_motor"/>
    <joint name="right_thumb/j4"/>
    <mechanicalReduction>1</mechanicalReduction>
    <motorTorqueConstant>1</motorTorqueConstant>
  </transmission>
  <transmission name="right_index_j0_trans" type="pr2_mechanism_model/SimpleTransmission">
    <actuator name="right_index_j0_motor"/>
    <joint name="right_index/j0"/>
    <mechanicalReduction>1</mechanicalReduction>
    <motorTorqueConstant>1</motorTorqueConstant>
  </transmission>
  <transmission name="right_index_j1_trans" type="pr2_mechanism_model/SimpleTransmission">
    <actuator name="right_index_j1_motor"/>
    <joint name="right_index/j1"/>
    <mechanicalReduction>1</mechanicalReduction>
    <motorTorqueConstant>1</motorTorqueConstant>
  </transmission>
  <transmission name="right_index_j2_trans" type="pr2_mechanism_model/SimpleTransmission">
    <actuator name="right_index_j2_motor"/>
    <joint name="right_index/j2"/>
    <mechanicalReduction>1</mechanicalReduction>
    <motorTorqueConstant>1</motorTorqueConstant>
  </transmission>
  <transmission name="right_index_j3_trans" type="pr2_mechanism_model/SimpleTransmission">
    <actuator name="right_index_j3_motor"/>
    <joint name="right_index/j3"/>
    <mechanicalReduction>1</mechanicalReduction>
    <motorTorqueConstant>1</motorTorqueConstant>
  </transmission>
  <transmission name="right_middle_j0_trans" type="pr2_mechanism_model/SimpleTransmission">
    <actuator name="right_middle_j0_motor"/>
    <joint name="right_middle/j0"/>
    <mechanicalReduction>1</mechanicalReduction>
    <motorTorqueConstant>1</motorTorqueConstant>
  </transmission>
  <transmission name="right_middle_j1_trans" type="pr2_mechanism_model/SimpleTransmission">
    <actuator name="right_middle_j1_motor"/>
    <joint name="right_middle/j1"/>
    <mechanicalReduction>1</mechanicalReduction>
    <motorTorqueConstant>1</motorTorqueConstant>
  </transmission>
  <transmission name="right_middle_j2_trans" type="pr2_mechanism_model/SimpleTransmission">
    <actuator name="right_middle_j2_motor"/>
    <joint name="right_middle/j2"/>
    <mechanicalReduction>1</mechanicalReduction>
    <motorTorqueConstant>1</motorTorqueConstant>
  </transmission>
  <transmission name="right_middle_j3_trans" type="pr2_mechanism_model/SimpleTransmission">
    <actuator name="right_middle_j3_motor"/>
    <joint name="right_middle/j3"/>
    <mechanicalReduction>1</mechanicalReduction>
    <motorTorqueConstant>1</motorTorqueConstant>
  </transmission>
  <transmission name="right_ring_j0_trans" type="pr2_mechanism_model/SimpleTransmission">
    <actuator name="right_ring_j0_motor"/>
    <joint name="right_ring/j0"/>
    <mechanicalReduction>1</mechanicalReduction>
    <motorTorqueConstant>1</motorTorqueConstant>
  </transmission>
  <transmission name="right_ring_j1_trans" type="pr2_mechanism_model/SimpleTransmission">
    <actuator name="right_ring_j1_motor"/>
    <joint name="right_ring/j1"/>
    <mechanicalReduction>1</mechanicalReduction>
    <motorTorqueConstant>1</motorTorqueConstant>
  </transmission>
  <transmission name="right_ring_j2_trans" type="pr2_mechanism_model/SimpleTransmission">
    <actuator name="right_ring_j2_motor"/>
    <joint name="right_ring/j2"/>
    <mechanicalReduction>1</mechanicalReduction>
    <motorTorqueConstant>1</motorTorqueConstant>
  </transmission>
  <transmission name="right_little_j0_trans" type="pr2_mechanism_model/SimpleTransmission">
    <actuator name="right_little_j0_motor"/>
    <joint name="right_little/j0"/>
    <mechanicalReduction>1</mechanicalReduction>
    <motorTorqueConstant>1</motorTorqueConstant>
  </transmission>
  <transmission name="right_little_j1_trans" type="pr2_mechanism_model/SimpleTransmission">
    <actuator name="right_little_j1_motor"/>
    <joint name="right_little/j1"/>
    <mechanicalReduction>1</mechanicalReduction>
    <motorTorqueConstant>1</motorTorqueConstant>
  </transmission>
  <transmission name="right_little_j2_trans" type="pr2_mechanism_model/SimpleTransmission">
    <actuator name="right_little_j2_motor"/>
    <joint name="right_little/j2"/>
    <mechanicalReduction>1</mechanicalReduction>
    <motorTorqueConstant>1</motorTorqueConstant>
  </transmission>
  <transmission name="neck_j0_trans" type="pr2_mechanism_model/SimpleTransmission">
    <actuator name="neck_j0_motor"/>
    <joint name="neck/j0"/>
    <mechanicalReduction>1</mechanicalReduction>
    <motorTorqueConstant>1</motorTorqueConstant>
  </transmission>
  <transmission name="neck_j1_trans" type="pr2_mechanism_model/SimpleTransmission">
    <actuator name="neck_j1_motor"/>
    <joint name="neck/j1"/>
    <mechanicalReduction>1</mechanicalReduction>
    <motorTorqueConstant>1</motorTorqueConstant>
  </transmission>
  <transmission name="neck_j2_trans" type="pr2_mechanism_model/SimpleTransmission">
    <actuator name="neck_j2_motor"/>
    <joint name="neck/j2"/>
    <mechanicalReduction>1</mechanicalReduction>
    <motorTorqueConstant>1</motorTorqueConstant>
  </transmission>
  <gazebo>
    <controller:gazebo_ros_controller_manager name="gazebo_ros_controller_manager" plugin="libgazebo_ros_controller_manager.so">
      <alwaysOn>true</alwaysOn>
      <updateRate>1000.0</updateRate>
      <interface:audio name="gazebo_ros_controller_manager_dummy_iface"/>
    </controller:gazebo_ros_controller_manager>
  </gazebo>
  <gazebo reference="left_camera_optical_frame">
    <sensor:camera name="r2/grasshopper2/left">
      <imageSize>1600 1200</imageSize>
      <imageFormat>R8G8B8</imageFormat>
      <hfov>90</hfov>
      <nearClip>0.10</nearClip>
      <farClip>50</farClip>
      <updateRate>10.0</updateRate>
      <controller:gazebo_ros_prosilica name="r2/grasshopper2/left_controller" plugin="libgazebo_ros_prosilica.so">
        <alwaysOn>true</alwaysOn>
        <updateRate>20.0</updateRate>
        <cameraName>r2/grasshopper2/left</cameraName>
        <imageTopicName>image_raw</imageTopicName>
        <cameraInfoTopicName>camera_info</cameraInfoTopicName>
        <pollServiceName>request_image</pollServiceName>
        <frameName>left_camera_optical_frame</frameName>
        <CxPrime>1224.5</CxPrime>
        <Cx>802.4</Cx>
        <Cy>603.2</Cy>
        <focalLength>8330</focalLength>
        <distortionK1>0.00000001</distortionK1>
        <distortionK2>0.00000001</distortionK2>
        <distortionK3>0.00000001</distortionK3>
        <distortionT1>0.00000001</distortionT1>
        <distortionT2>0.00000001</distortionT2>
        <interface:camera name="r2/grasshopper2/left_iface"/>
      </controller:gazebo_ros_prosilica>
    </sensor:camera>
    <turnGravityOff>false</turnGravityOff>
    <material>Gazebo/White</material>
  </gazebo>
  <gazebo reference="right_camera_optical_frame">
    <sensor:camera name="r2/grasshopper2/right">
      <imageSize>1600 1200</imageSize>
      <imageFormat>R8G8B8</imageFormat>
      <hfov>90</hfov>
      <nearClip>0.10</nearClip>
      <farClip>50</farClip>
      <updateRate>10.0</updateRate>
      <controller:gazebo_ros_prosilica name="r2/grasshopper2/right_controller" plugin="libgazebo_ros_prosilica.so">
        <alwaysOn>true</alwaysOn>
        <updateRate>20.0</updateRate>
        <cameraName>r2/grasshopper2/right</cameraName>
        <imageTopicName>image_raw</imageTopicName>
        <cameraInfoTopicName>camera_info</cameraInfoTopicName>
        <pollServiceName>request_image</pollServiceName>
        <frameName>right_camera_optical_frame</frameName>
        <CxPrime>1224.5</CxPrime>
        <Cx>802.4</Cx>
        <Cy>603.2</Cy>
        <focalLength>8330</focalLength>
        <distortionK1>0.00000001</distortionK1>
        <distortionK2>0.00000001</distortionK2>
        <distortionK3>0.00000001</distortionK3>
        <distortionT1>0.00000001</distortionT1>
        <distortionT2>0.00000001</distortionT2>
        <interface:camera name="r2/grasshopper2/right_iface"/>
      </controller:gazebo_ros_prosilica>
    </sensor:camera>
    <turnGravityOff>false</turnGravityOff>
    <material>Gazebo/White</material>
  </gazebo>
  <joint name="asus_asus_ir_joint" type="fixed">
    <!-- <origin xyz="-0.032267 0.0125 0.136453" rpy="0 0 0"/> -->
    <origin rpy="0 0 0" xyz="0 0 0"/>
    <parent link="simulated_asus_frame"/>
    <child link="asus_asus_ir_link"/>
  </joint>
  <link name="asus_asus_ir_link">
    <inertial>
      <mass value="0.1"/>
      <origin rpy="0 0 0" xyz="0 0 0"/>
      <inertia ixx="0.01" ixy="0.0" ixz="0.0" iyy="0.01" iyz="0.0" izz="0.01"/>
    </inertial>
    <!--
        <visual>
        <origin xyz="0.0 0.0 0" rpy="0 0 0"/>
        <geometry>
          <sphere radius="0.0005"/>
        </geometry>
      </visual>
      <collision>
        <origin xyz="0.0 0.0 0" rpy="0 0 0"/>
        <geometry>
          <sphere radius="0.0005"/>
        </geometry>
      </collision>
-->
  </link>
  <joint name="asus_asus_ir_optical_frame_joint" type="fixed">
    <origin rpy="-1.57 0 -1.57" xyz="0 0 0"/>
    <!-- this works for non-rgb 3d data... -->
    <parent link="asus_asus_ir_link"/>
    <child link="asus_asus_ir_optical_frame"/>
  </joint>
  <link name="asus_asus_ir_optical_frame">
    <inertial>
      <mass value=".1"/>
      <inertia ixx=".0010" ixy="0.0" ixz="0.0" iyy=".0010" iyz="0.0" izz=".0010"/>
    </inertial>
  </link>
  <gazebo reference="asus_asus_ir_link">
    <sensor:camera name="asus_ir_sensor">
      <imageFormat>L8</imageFormat>
      <imageSize>640 480</imageSize>
      <hfov>57</hfov>
      <nearClip>0.01</nearClip>
      <farClip>5</farClip>
      <updateRate>1.0</updateRate>
      <baseline>0.2</baseline>
      <controller:gazebo_ros_openni_kinect name="asus_asus_ir_link_controller" plugin="libgazebo_ros_openni_kinect.so">
        <alwaysOn>true</alwaysOn>
        <updateRate>1.0</updateRate>
        <cameraName>head_mount_asus_ir</cameraName>
        <imageTopicName>/head_mount_asus/depth/image_raw</imageTopicName>
        <cameraInfoTopicName>/head_mount_asus/depth/camera_info</cameraInfoTopicName>
        <depthImageTopicName>/head_mount_asus/depth/image_raw</depthImageTopicName>
        <depthImageInfoTopicName>/head_mount_asus/depth/camera_info</depthImageInfoTopicName>
        <pointCloudTopicName>/head_mount_asus/depth/points</pointCloudTopicName>
        <frameName>asus_asus_ir_optical_frame</frameName>
        <pointCloudCutoff>0.5</pointCloudCutoff>
        <distortionK1>0.00000001</distortionK1>
        <distortionK2>0.00000001</distortionK2>
        <distortionK3>0.00000001</distortionK3>
        <distortionT1>0.00000001</distortionT1>
        <distortionT2>0.00000001</distortionT2>
      </controller:gazebo_ros_openni_kinect>
    </sensor:camera>
    <material value="Gazebo/Red"/>
  </gazebo>
  <joint name="asus_asus_rgb_joint" type="fixed">
    <origin rpy="3.14 0 0" xyz="0 -0.03 0"/>
    <parent link="asus_asus_ir_link"/>
    <child link="asus_asus_rgb_link"/>
  </joint>
  <link name="asus_asus_rgb_link">
    <inertial>
      <mass value=".1"/>
      <inertia ixx=".0010" ixy="0.0" ixz="0.0" iyy=".0010" iyz="0.0" izz=".0010"/>
    </inertial>
    <!-- <visual>
        <origin xyz="0.0 0.0 0" rpy="0 0 0"/>
        <geometry>
          <sphere radius="0.0005"/>
        </geometry>
      </visual>
      <collision>
        <origin xyz="0.0 0.0 0" rpy="0 0 0"/>
        <geometry>
          <sphere radius="0.0005"/>
        </geometry>
      </collision> -->
  </link>
  <joint name="asus_asus_rgb_optical_frame_joint" type="fixed">
    <origin rpy="-1.57 0 -1.57" xyz="0 0 0"/>
    <parent link="asus_asus_rgb_link"/>
    <child link="asus_asus_rgb_optical_frame"/>
  </joint>
  <link name="asus_asus_rgb_optical_frame">
    <inertial>
      <mass value=".1"/>
      <inertia ixx=".0010" ixy="0.0" ixz="0.0" iyy=".0010" iyz="0.0" izz=".0010"/>
    </inertial>
  </link>
  <gazebo reference="asus_asus_rgb_link">
    <sensor:camera name="asus_rgb_sensor">
      <imageFormat>R8G8B8</imageFormat>
      <imageSize>640 480</imageSize>
      <hfov>57</hfov>
      <nearClip>0.01</nearClip>
      <farClip>5</farClip>
      <updateRate>1.0</updateRate>
      <baseline>0.2</baseline>
      <controller:gazebo_ros_openni_kinect name="asus_asus_rgb_link_controller" plugin="libgazebo_ros_openni_kinect.so">
        <alwaysOn>true</alwaysOn>
        <updateRate>1.0</updateRate>
        <cameraName>head_mount_asus_rgb</cameraName>
        <imageTopicName>/head_mount_asus/rgb/image_raw</imageTopicName>
        <cameraInfoTopicName>/head_mount_asus/rgb/camera_info</cameraInfoTopicName>
        <pointCloudTopicName>/head_mount_asus/depth_registered/points</pointCloudTopicName>
        <frameName>asus_asus_rgb_optical_frame</frameName>
        <pointCloudCutoff>0.5</pointCloudCutoff>
        <distortionK1>0.00000001</distortionK1>
        <distortionK2>0.00000001</distortionK2>
        <distortionK3>0.00000001</distortionK3>
        <distortionT1>0.00000001</distortionT1>
        <distortionT2>0.00000001</distortionT2>
      </controller:gazebo_ros_openni_kinect>
    </sensor:camera>
    <material value="Gazebo/Red"/>
  </gazebo>
</robot>

