<?xml version="1.0"?>
<robot>

  <link name="neck_base">
    <visual>
      <geometry>
         <mesh filename="package://r2_description/meshes/Neck_Lower.dae"/>
      </geometry>
      <origin rpy="-1.57 1.57 0" xyz="0.0 0.0 0.0"/>
    </visual>
    <inertial>
      <mass value=".1"/>
      <inertia ixx=".0010" ixy="0.0" ixz="0.0" iyy=".0010" iyz="0.0" izz=".0010"/>
    </inertial>
    <collision>
      <geometry>
         <mesh filename="package://r2_description/meshes/Neck_Lower.dae"/>
      </geometry>
      <origin rpy="-1.57 1.57 0" xyz="0.0 0.0 0.0"/>
    </collision>
  </link>
  
  <link name="neck_lower_pitch">
   <visual>
      <geometry>
         <mesh filename="package://r2_description/meshes/Neck_Upper.dae"/>
      </geometry>
      <origin rpy="0 0 1.57" xyz="0.075 0.0 0.0"/>
    </visual>
    <inertial>
      <mass value=".1"/>
      <inertia ixx=".0010" ixy="0.0" ixz="0.0" iyy=".0010" iyz="0.0" izz=".0010"/>
    </inertial>
    <collision>
      <geometry>
         <mesh filename="package://r2_description/meshes/Neck_Upper.dae"/>
      </geometry>
      <origin rpy="0 0 1.57" xyz="0.075 0.0 0.0"/>
    </collision>
  </link>
  
  <link name="neck_roll">
    <visual>
      <geometry>
         <mesh filename="package://r2_description/meshes/Head.dae"/>
      </geometry>
      <origin rpy="0 1.57 0" xyz="-0.0 0.07 0.0"/>
    </visual>
    <collision>
      <geometry>
         <mesh filename="package://r2_description/meshes/Head.dae"/>
      </geometry>
      <origin rpy="0 1.57 0" xyz="-0.0 0.07 0.0"/>
    </collision>
    <inertial>
      <mass value=".1"/>
      <inertia ixx=".0010" ixy="0.0" ixz="0.0" iyy=".0010" iyz="0.0" izz=".0010"/>
    </inertial>
  </link>
  
  <link name="neck_upper_pitch">
    <inertial>
      <mass value=".1"/>
      <inertia ixx=".0010" ixy="0.0" ixz="0.0" iyy=".0010" iyz="0.0" izz=".0010"/>
    </inertial>
  </link>

 <!-- simulated asus --> 
 <link name="simulated_asus_frame">
    <inertial>
      <mass value=".01"/>
      <inertia ixx=".0010" ixy="0.0" ixz="0.0" iyy=".0010" iyz="0.0" izz=".0010"/>
    </inertial>
  </link>

 <!-- actual asus --> 
 <link name="asus_frame">
    <inertial>
      <mass value=".01"/>
      <inertia ixx=".0010" ixy="0.0" ixz="0.0" iyy=".0010" iyz="0.0" izz=".0010"/>
    </inertial>
  </link>

 <!-- asus default --> 
 <link name="openni_depth_frame">
    <inertial>
      <mass value=".01"/>
      <inertia ixx=".0010" ixy="0.0" ixz="0.0" iyy=".0010" iyz="0.0" izz=".0010"/>
    </inertial>
  </link>


  <!--visions --> 
  <link name="vision_center_frame">
    <inertial>
      <mass value=".1"/>
      <inertia ixx=".0010" ixy="0.0" ixz="0.0" iyy=".0010" iyz="0.0" izz=".0010"/>
    </inertial>
  </link>
  
  <link name="left_camera_frame">
    <inertial>
      <mass value=".1"/>
      <inertia ixx=".0010" ixy="0.0" ixz="0.0" iyy=".0010" iyz="0.0" izz=".0010"/>
    </inertial>
  </link>
 
  <link name="right_camera_frame">
    <inertial>
      <mass value=".1"/>
      <inertia ixx=".0010" ixy="0.0" ixz="0.0" iyy=".0010" iyz="0.0" izz=".0010"/>
    </inertial>
  </link>

<link name="left_camera_optical_frame">
    <inertial>
      <mass value=".1"/>
      <inertia ixx=".0010" ixy="0.0" ixz="0.0" iyy=".0010" iyz="0.0" izz=".0010"/>
    </inertial>
  </link>loading model xml from ros parameter

 
  <link name="right_camera_optical_frame">
    <inertial>
      <mass value=".1"/>
      <inertia ixx=".0010" ixy="0.0" ixz="0.0" iyy=".0010" iyz="0.0" izz=".0010"/>
    </inertial>
  </link>


 <joint name="neck/j0" type="revolute">
    <parent link="waist_center"/>
    <child link="neck_base"/>
    <origin rpy=" -1.570796 -0.0 0.0 " xyz=" 0.08636 0.0 -0.6142228 "/>
    <dynamics damping="1.0" />
    <axis xyz="0 0 1"/>
    <limit effort="100000.0" lower="-0.7" upper="0.175" velocity="1000"/>
  </joint>
  <joint name="neck/j1" type="revolute">
    <parent link="neck_base"/>
    <child link="neck_lower_pitch"/>
    <origin rpy=" -1.570796 -0.0 0.0 " xyz=" -0.0762 -0.0 0.0 "/>
    <dynamics damping="1.0" />
    <axis xyz="0 0 1"/>
    <limit effort="100000.0" lower="-1.22" upper="1.22" velocity="1000"/>
  </joint>
  <joint name="neck/j2" type="revolute">
    <parent link="neck_lower_pitch"/>
    <child link="neck_roll"/>
    <origin rpy=" 1.570796 -0.0 0.0 " xyz=" 0.0508 0.0 0.1777619 "/>
    <dynamics damping="1.0" />
    <axis xyz="0 0 1"/>
    <limit effort="100000.0" lower="-0.7" upper="0.175" velocity="1000"/>
  </joint>
  <joint name="head" type="fixed">
    <parent link="neck_roll"/>
    <child link="neck_upper_pitch"/>
    <origin rpy=" 1.570796 -0.0 0.0 " xyz=" 0.0 0.0 0.0 "/>
  </joint>
  <joint name="asus" type="fixed">
    <parent link="neck_upper_pitch"/>
    <child link="asus_frame"/>
     <origin rpy="1.50 0.0 1.57 " xyz="0.12 -0.015 -0.14 "/> 
<!-- OK    <origin rpy="1.45 0 1.57 " xyz="0.11 -0.040 -0.15 "/>  -->
<!-- ORIGINAL     <origin rpy="1.57 0 1.57 " xyz="0.066675 -0.0508 -0.116205 "/>  -->
  </joint>
  <joint name="openni" type="fixed">
    <parent link="asus_frame"/>
    <child link="openni_depth_frame"/>
    <origin rpy="1.57 -1.57 0 " xyz="0 0 0 "/> 
  </joint>
  <joint name="simulated_asus" type="fixed">
    <parent link="neck_upper_pitch"/>
    <child link="simulated_asus_frame"/>
    <dynamics damping="1.0" />
    <origin rpy="0 0 0" xyz="0.12 -0.015 -0.14 "/> 
  </joint>
  <joint name="vision" type="fixed">
    <parent link="neck_upper_pitch"/>
    <child link="vision_center_frame"/>
    <dynamics damping="1.0" />
    <origin rpy="1.57 -1.57 1.57" xyz=" 0.066675 0.0 -0.116205 "/> 
  </joint>
  <joint name="vision_right" type="fixed">
    <parent link="vision_center_frame"/>
    <child link="right_camera_frame"/>
    <dynamics damping="1.0" />
    <origin rpy="0 0 1.57" xyz="0.0087 -0.04887 0.01789"/> 
  </joint>
  <joint name="vision_left" type="fixed">
    <parent link="vision_center_frame"/>
    <child link="left_camera_frame"/>
    <dynamics damping="1.0" />
    <origin rpy="0 0 1.57" xyz="0.0087 0.04887 0.01789"/> 
  </joint>
  <joint name="right_optical" type="fixed">
    <parent link="right_camera_frame"/>
    <child link="right_camera_optical_frame"/>
    <dynamics damping="1.0" />
    <origin rpy="-1.57 -1.57 0" xyz="0 0 0"/> 
  </joint>
  <joint name="left_optical" type="fixed">
    <parent link="left_camera_frame"/>
    <child link="left_camera_optical_frame"/>
    <dynamics damping="1.0" />
    <origin rpy="-1.57 -1.57 0" xyz="0 0 0"/> 
  </joint>


</robot> 
