<?xml version="1.0"?>
<robot>

  <link name="left_shoulder_roll">
    <visual>
      <geometry>
        <mesh filename="package://r2_description/meshes/Left_Shoulder_Upper.dae"/>
      </geometry>
      <material name="dirty_white"/>
      <origin rpy="0 0 1.57" xyz="0 0 .08"/>
    </visual>
    <collision>
      <geometry>
        <mesh filename="package://r2_description/meshes/Left_Shoulder_Upper.dae"/>
      </geometry>
      <origin rpy="0 0 1.57" xyz="0 0 .08"/>
    </collision>
    <inertial>
	<origin xyz="-0.0089916 -0.00131572   0.10287   "/> 
        <mass value="6.168856232"/>
        <inertia ixx="0.0198585269"  ixy="-0.0060195977"  ixz="-0.0003950635"  iyy="0.0671900643"  iyz="0.00012683"  izz="0.0634150128"/>
    </inertial>
  </link>
  
<!--
  <link name="left_shoulder_roll_mass"/>
-->

  <link name="left_shoulder_pitch">
    <visual>
      <geometry>
        <mesh filename="package://r2_description/meshes/Left_Shoulder_Lower.dae"/>
      </geometry>
      <material name="dirty_white"/>
      <origin rpy=".0 0 -1.57" xyz="0 0 0"/>
    </visual>
    <collision>
      <geometry>
        <mesh filename="package://r2_description/meshes/Left_Shoulder_Lower.dae"/>
      </geometry>
      <origin rpy=".0 0 -1.57" xyz="0 0 0"/>
    </collision>
     <inertial>
        <origin xyz="0.037084 -0.00028448   0.0077978   "/>
        <mass value="4.4270615312"/>
        <inertia ixx="0.02701064"  ixy="0.001512947"  ixz="-0.000052382497887"  iyy="0.0113836825"  iyz="0.0000217138622526"  izz="0.0251962741"/>
    </inertial>
  </link>

<!--
  <link name="left_shoulder_pitch_mass"/>
-->

  <link name="left_upper_arm">
    <visual>
      <geometry>
        <mesh filename="package://r2_description/meshes/Left_Upper_Arm.dae"/>
      </geometry>
      <material name="dirty_white"/>
      <origin rpy="0 0 3.14" xyz="0 0 .1016"/>
    </visual>
    <collision>
      <geometry>
        <mesh filename="package://r2_description/meshes/Left_Upper_Arm.dae"/>
      </geometry>
      <origin rpy="0 0 3.14" xyz="0 0 .1016"/>
    </collision>
    <inertial>
        <origin xyz="-0.0074168 -0.041402   0.1016   "/>
        <mass value="4.853438359"/>        
        <inertia ixx="0.016007389"  ixy="-0.00339462"  ixz="0.0065843922"  iyy="0.0462370652"  iyz="0.0013754064"  izz="0.04214011"/>
    </inertial>
  </link>

<!--
 <link name="left_upper_arm_mass"/>
-->

  <link name="left_elbow">
    <visual>
      <geometry>
        <mesh filename="package://r2_description/meshes/Left_Elbow.dae"/>
      </geometry>
      <material name="dirty_white"/>
      <origin rpy="0 0 -1.57" xyz="0 0 0"/>
    </visual>
    <collision>
      <geometry>
        <mesh filename="package://r2_description/meshes/Left_Elbow.dae"/>
      </geometry>
      <origin rpy="0 0 -1.57" xyz="0 0 0"/>
    </collision>
    <inertial>
        <origin xyz="0.026162 0.033782   0.0154432   "/>
        <mass value="2.9710300235"/>
        <inertia ixx="0.0120274897"  ixy="0.0016417085"  ixz="-0.001188117"  iyy="0.0088377175"  iyz="0.0031605083"  izz="0.0105350275"/>
    </inertial>
  </link>

<!--
 <link name="left_elbow_mass"/>
-->

  <link name="left_lower_arm">
    <visual>
      <geometry>
        <mesh filename="package://r2_description/meshes/Left_Forearm.dae"/>
      </geometry>
      <origin xyz="0 0 0.1"/>
      <material name="dirty_white"/>
    </visual>
    <collision>
      <geometry>
        <mesh filename="package://r2_description/meshes/Left_Forearm.dae"/>
      </geometry>
      <origin xyz="0 0 0.1"/>
    </collision>
    <inertial>
        <origin xyz="0.0003556 -0.00122682   0.17653   "/>
        <mass value="6.939963261"/>
        <inertia ixx="0.0125249771"  ixy="-0.0002446467"  ixz="0.0005208986"  iyy="0.0395063532"  iyz="-0.0001691457"  izz="0.0403842721"/>
    </inertial>
  </link>

<!--
  <link name="left_lower_arm_mass"/>
-->

  <link name="left_wrist_pitch">
    <inertial>
        <origin xyz="-0.004064   0.000000152908   -0.00092202"/>
        <mass value="0.1165732391"/>
        <inertia ixx="0.00005765"  ixy="0.00000000004360"  ixz="0.00000175876"  iyy="0.0000169438359087"  iyz="0.000000054430975458"  izz="0.000044188587603"/>
    </inertial>
  </link>

<!--
 <link name="left_wrist_pitch_mass"/>
-->

  <link name="left_wrist_yaw">
    <inertial>
        <origin xyz="-0.00090932   -0.0253746  0.067564     "/>
        <mass value="1.1884120094"/>
        <inertia ixx="0.0044481227"  ixy="0.0003716524"  ixz="0.0001024239"  iyy="0.0030141884"  iyz="0.000101546"  izz="0.001992876"/>
    </inertial>
  </link>

<!--
 <link name="left_wrist_yaw_mass"/>
-->

  <link name="left_palm">
    <visual>
      <geometry>
        <mesh filename="package://r2_description/meshes/Left_Palm.dae"/>
      </geometry>
      <origin xyz="0.0 0.0 -0.0" rpy="3.14 0 1.57"/>
    </visual>
    <collision>
      <geometry>
        <mesh filename="package://r2_description/meshes/Left_Palm.dae"/>
      </geometry>
      <origin xyz="0.0 0.0 -0.0" rpy="3.14 0 1.57"/>
    </collision>
    <inertial>
        <origin xyz="0.067564   -0.0253746   -0.00090932"/>
        <mass value="1.1884120094"/>
        <inertia ixx="0.001992876"  ixy="0.000101546"  ixz="0.0001024239"  iyy="0.0030141884"  iyz="0.0003716524"  izz="0.0044481227"/>
    </inertial>
  </link>

  <joint name="left/j0" type="revolute">
    <parent link="chest_base"/>
    <child link="left_shoulder_roll"/>
    <origin rpy=" -1.5664 -0.0 -2.8802 " xyz=" -0.0 -0.0 0.0 "/>
    <axis xyz="0 0 1"/>
    <dynamics damping="10.0" />
    <limit effort="100.0" lower="-1.57" upper="1.57" velocity="1000"/>
  </joint>
  <joint name="left/j1" type="revolute">
    <parent link="left_shoulder_roll"/>
    <child link="left_shoulder_pitch"/>
    <origin rpy=" -1.5701 -0.0 1.570796 " xyz=" 0.0 0.0 0.316611 "/>
    <axis xyz="0 0 1"/>
    <dynamics damping="10.0" />
    <limit effort="100.0" lower="-1.66" upper=".175" velocity="1000"/>
  </joint>
  <joint name="left/j2" type="revolute">
    <parent link="left_shoulder_pitch"/>
    <child link="left_upper_arm"/>
    <origin rpy=" 1.57 -0.0 0.0 " xyz=" 0.0 0.0 0.0 "/>
    <axis xyz="0 0 1"/>
    <dynamics damping="1.0" />
    <!-- limits expanded because Gazebo starts up at zero causing stability issues-->
<!--    <limit effort="100.0" lower="-4.89" upper="-0.79" velocity="1000"/>-->
    <limit effort="100.0" lower="-5.68" upper="0.0" velocity="1000"/>
  </joint>u
  <joint name="left/j3" type="revolute">
    <parent link="left_upper_arm"/>
    <child link="left_elbow"/>
    <origin rpy=" -1.5748 -0.0 0.0 " xyz=" -0.05437886 -0.0 0.3564382 "/>
    <axis xyz="0 0 1"/>
    <dynamics damping="1.0" />
    <!-- limits expanded because Gazebo starts up at zero causing stability issues-->
<!--    <limit effort="100.0" lower="-2.79" upper="-.087" velocity="1000"/>-->
    <limit effort="100.0" lower="-2.877" upper="0.0" velocity="1000"/>
  </joint>
  <joint name="left/j4" type="revolute">
    <parent link="left_elbow"/>
    <child link="left_lower_arm"/>
    <origin rpy=" 1.5738 -0.0 0.0 " xyz=" 0.0540385 0.0 0.0 "/>
    <axis xyz="0 0 1"/>
    <dynamics damping="1.0" />
    <limit effort="100.0" lower="-1.3" upper="4.45" velocity="1000"/>
  </joint>
  <joint name="left/j5" type="revolute">
    <parent link="left_lower_arm"/>
    <child link="left_wrist_pitch"/>
    <origin rpy=" -1.5952 -0.0 0.0 " xyz=" 0.0 0.0 0.3570478 "/>
    <axis xyz="0 0 1"/>
    <dynamics damping="1.0" />
    <limit effort="100.0" lower="-1.22" upper="1.22" velocity="1000"/>
  </joint>
  <joint name="left/j6" type="revolute">
    <parent link="left_wrist_pitch"/>
    <child link="left_wrist_yaw"/>
    <origin rpy=" 1.6505 -0.0 -1.5727 " xyz=" -0.00001156 -0.006072621 0.0 "/>
    <axis xyz="0 0 1"/>
    <dynamics damping="1.0" />
    <limit effort="100.0" lower="-0.785" upper="0.785" velocity="1000"/>
  </joint>
  <joint name="left/j7" type="fixed">
    <parent link="left_wrist_yaw"/>
    <child link="left_palm"/>
    <origin rpy=" 0.0 -0.0 -0.014 " xyz=" 0.0 -0.0 0.0 "/>
  </joint>

<!--
  <joint name="left/m0" type="fixed">
    <parent link="left_shoulder_roll"/>
    <child link="left_shoulder_roll_mass"/>
    <origin xyz="-0.00131572   -0.0089916 0.10287   "/> 
  </joint>


  <joint name="left/m1" type="fixed">
    <parent link="left_shoulder_pitch"/>
    <child link="left_shoulder_pitch_mass"/>
    <origin xyz="-0.00028448   0.037084 0.0077978   "/>
  </joint>


  <joint name="left/m2" type="fixed">
    <parent link="left_upper_arm"/>
    <child link="left_upper_arm_mass"/>
    <origin xyz=" -0.041402 -0.0074168    0.1016   "/>
  </joint>


  <joint name="left/m3" type="fixed">
    <parent link="left_elbow"/>
    <child link="left_elbow_mass"/>
    <origin xyz="0.033782  0.026162 0.0154432"/>
  </joint>

<joint name="left/m4" type="fixed">
    <parent link="left_lower_arm"/>
    <child link="left_lower_arm_mass"/>
    <origin xyz="0.0003556 -0.00122682 0.17653 "/>
</joint>


<joint name="left/m5" type="fixed">
    <parent link="left_wrist_pitch"/>
    <child link="left_wrist_pitch_mass"/>
    <origin xyz="-0.00092202 -0.004064   0.000000152908   "/>
</joint>

<joint name="left/m6" type="fixed">
    <parent link="left_wrist_yaw"/>
    <child link="left_wrist_yaw_mass"/>
    <origin xyz="0.067564   -0.00090932 -0.0253746   "/>
</joint>

-->

</robot>
