<?xml version="1.0"?>
<robot>

  <link name="left_thumb_base">
    <inertial>
      <mass value=".05"/>
      <inertia ixx=".0010" ixy="0.0" ixz="0.0" iyy=".0010" iyz="0.0" izz=".0010"/>
    </inertial>
  </link>
  
  <link name="left_thumb_proximal">
    <inertial>
      <mass value=".0010"/>
      <inertia ixx=".0010" ixy="0.0" ixz="0.0" iyy=".0010" iyz="0.0" izz=".0010"/>
    </inertial>
    <visual>
      <geometry>
        <mesh filename="package://r2_description/meshes/Left_Thumb_Carp.dae"/>
      </geometry>
      <origin xyz="-0.01 0.0 0.0" rpy="-1.57 0 0"/>
    </visual>
    <collision>
      <geometry>
        <mesh filename="package://r2_description/meshes/Left_Thumb_Carp.dae"/>
      </geometry>
      <origin xyz="-0.01 0.0 0.0" rpy="-1.57 0 0"/>
    </collision>
  </link>
  
  <link name="left_thumb_medial_prime">
    <inertial>
      <mass value=".0010"/>
      <inertia ixx=".0010" ixy="0.0" ixz="0.0" iyy=".0010" iyz="0.0" izz=".0010"/>
    </inertial>
     <visual>
       <geometry>
        <mesh filename="package://r2_description/meshes/Left_Thumb_MtCar.dae"/>
      </geometry>
      <origin xyz="-0.0 0 0.0" rpy="-1.57 -1.57 0"/>
    </visual>
    <collision>
      <geometry>
        <mesh filename="package://r2_description/meshes/Left_Thumb_MtCar.dae"/>
      </geometry>
      <origin xyz="0.0 0.0 0.0" rpy="-1.57 -1.57 0"/>
    </collision>
  </link>
  
  <link name="left_thumb_medial">
    <inertial>
      <mass value=".0010"/>
      <inertia ixx=".0010" ixy="0.0" ixz="0.0" iyy=".0010" iyz="0.0" izz=".0010"/>
    </inertial>
    <visual>
       <geometry>
        <mesh filename="package://r2_description/meshes/Thumb_Proximal.dae"/>
      </geometry>
      <origin xyz="0.0 0.0 0.0" rpy="3.14 0 1.57"/>
    </visual>
    <collision>
      <geometry>
        <mesh filename="package://r2_description/meshes/Thumb_Proximal.dae"/>
      </geometry>
      <origin xyz="0.0 0.0 0.0" rpy="3.14 0 1.57"/>
    </collision>
  </link>
 
  <link name="left_thumb_distal">
    <inertial>
      <mass value=".0010"/>
      <inertia ixx=".0010" ixy="0.0" ixz="0.0" iyy=".0010" iyz="0.0" izz=".0010"/>
    </inertial>
    <visual>
       <geometry>
        <mesh filename="package://r2_description/meshes/Thumb_Dist.dae"/>
      </geometry>
      <origin xyz="0.0 0.0 0.0" rpy="3.14 3.14 0"/>
    </visual>
    <collision>
      <geometry>
        <mesh filename="package://r2_description/meshes/Thumb_Dist.dae"/>
      </geometry>
      <origin xyz="0.0 0.0 0.0" rpy="3.14 3.14 0"/>
    </collision>
  </link>

  <link name="left_thumb_tip">
    <inertial>
      <mass value=".0010"/>
      <inertia ixx=".0010" ixy="0.0" ixz="0.0" iyy=".0010" iyz="0.0" izz=".0010"/>
    </inertial>
  </link>

  <link name="left_index_base">
    <inertial>
      <mass value=".0010"/>
      <inertia ixx=".0010" ixy="0.0" ixz="0.0" iyy=".0010" iyz="0.0" izz=".0010"/>
    </inertial>
  </link>
  
  <link name="left_index_proximal">
    <inertial>
      <mass value=".0010"/>
      <inertia ixx=".0010" ixy="0.0" ixz="0.0" iyy=".0010" iyz="0.0" izz=".0010"/>
    </inertial>
    <visual>
      <geometry>
        <mesh filename="package://r2_description/meshes/Finger_Proximal.dae"/>
      </geometry>
      <origin xyz="0.0 0.0 0.0" rpy="0 0 1.57"/>
    </visual>
    <collision>
      <geometry>
        <mesh filename="package://r2_description/meshes/Finger_Proximal.dae"/>
      </geometry>
      <origin xyz="0.0 0.0 0.0" rpy="0 0 1.57"/>
    </collision>
 </link>
  
  <link name="left_index_medial">
    <inertial>
      <mass value=".0010"/>
      <inertia ixx=".0010" ixy="0.0" ixz="0.0" iyy=".0010" iyz="0.0" izz=".0010"/>
    </inertial>
    <visual>
      <geometry>
        <mesh filename="package://r2_description/meshes/Finger_Mid.dae"/>
      </geometry>
      <origin xyz="0.0 0.0 0.0" rpy="3.14 0 1.57"/>
    </visual>
    <collision>
      <geometry>
        <mesh filename="package://r2_description/meshes/Finger_Mid.dae"/>
      </geometry>
      <origin xyz="0.0 0.0 0.0" rpy="3.14 0 1.57"/>
    </collision>
  </link>

  <link name="left_index_distal">
    <inertial>
      <mass value=".0010"/>
      <inertia ixx=".0010" ixy="0.0" ixz="0.0" iyy=".0010" iyz="0.0" izz=".0010"/>
    </inertial>
    <visual>
      <geometry>
        <mesh filename="package://r2_description/meshes/Finger_Dist.dae"/>
      </geometry>
      <origin xyz="0.0 0.0 0.0" rpy="0 -1.57 0"/>
    </visual>
    <collision>
      <geometry>
        <mesh filename="package://r2_description/meshes/Finger_Dist.dae"/>
      </geometry>
      <origin xyz="0.0 0.0 0.0" rpy="0 -1.57 0"/>
    </collision>
  </link>

  <link name="left_index_tip">
    <inertial>
      <mass value=".0010"/>
      <inertia ixx=".0010" ixy="0.0" ixz="0.0" iyy=".0010" iyz="0.0" izz=".0010"/>
    </inertial>
  </link>


  <link name="left_middle_base">
    <inertial>
      <mass value=".0010"/>
      <inertia ixx=".0010" ixy="0.0" ixz="0.0" iyy=".0010" iyz="0.0" izz=".0010"/>
    </inertial>
  </link>
  
  <link name="left_middle_proximal">
    <inertial>
      <mass value=".0010"/>
      <inertia ixx=".0010" ixy="0.0" ixz="0.0" iyy=".0010" iyz="0.0" izz=".0010"/>
    </inertial>
    <visual>
      <geometry>
        <mesh filename="package://r2_description/meshes/Finger_Proximal.dae"/>
      </geometry>
      <origin xyz="0.0 0.0 0.0" rpy="0 0 1.57"/>
    </visual>
    <collision>
      <geometry>
        <mesh filename="package://r2_description/meshes/Finger_Proximal.dae"/>
      </geometry>
      <origin xyz="0.0 0.0 0.0" rpy="0 0 1.57"/>
    </collision>
  </link>

  <link name="left_middle_medial">
    <inertial>
      <mass value=".0010"/>
      <inertia ixx=".0010" ixy="0.0" ixz="0.0" iyy=".0010" iyz="0.0" izz=".0010"/>
    </inertial>
    <visual>
      <geometry>
        <mesh filename="package://r2_description/meshes/Finger_Mid.dae"/>
      </geometry>
      <origin xyz="0.0 0.0 0.0" rpy="3.14 0 1.57"/>
    </visual>
    <collision>
      <geometry>
        <mesh filename="package://r2_description/meshes/Finger_Mid.dae"/>
      </geometry>
      <origin xyz="0.0 0.0 0.0" rpy="3.14 0 1.57"/>
    </collision>
  </link>
  
  <link name="left_middle_distal">
    <inertial>
      <mass value=".0010"/>
      <inertia ixx=".0010" ixy="0.0" ixz="0.0" iyy=".0010" iyz="0.0" izz=".0010"/>
    </inertial>
    <visual>
      <geometry>
        <mesh filename="package://r2_description/meshes/Finger_Dist.dae"/>
      </geometry>
      <origin xyz="0.0 0.0 0.0" rpy="0 -1.57 0"/>
    </visual>
    <collision>
      <geometry>
        <mesh filename="package://r2_description/meshes/Finger_Dist.dae"/>
      </geometry>
      <origin xyz="0.0 0.0 0.0" rpy="0 -1.57 0"/>
    </collision>
  </link>
  
  <link name="left_middle_tip">
    <inertial>
      <mass value=".0010"/>
      <inertia ixx=".0010" ixy="0.0" ixz="0.0" iyy=".0010" iyz="0.0" izz=".0010"/>
    </inertial>
  </link>
  

  <link name="left_ring_proximal">
    <inertial>
      <mass value=".0010"/>
      <inertia ixx=".0010" ixy="0.0" ixz="0.0" iyy=".0010" iyz="0.0" izz=".0010"/>
    </inertial>
    <visual>
      <geometry>
        <mesh filename="package://r2_description/meshes/Finger_Proximal.dae"/>
      </geometry>
      <origin xyz="0.0 0.0 0.0" rpy="0 0 1.57"/>
    </visual>
    <collision>
      <geometry>
        <mesh filename="package://r2_description/meshes/Finger_Proximal.dae"/>
      </geometry>
      <origin xyz="0.0 0.0 0.0" rpy="0 0 1.57"/>
    </collision>
  </link>

  <link name="left_ring_medial">
    <inertial>
      <mass value=".0010"/>
      <inertia ixx=".0010" ixy="0.0" ixz="0.0" iyy=".0010" iyz="0.0" izz=".0010"/>
    </inertial>
    <visual>
      <geometry>
        <mesh filename="package://r2_description/meshes/Finger_Mid.dae"/>
      </geometry>
      <origin xyz="0.0 0.0 0.0" rpy="3.14 0 1.57"/>
    </visual>
    <collision>
      <geometry>
        <mesh filename="package://r2_description/meshes/Finger_Mid.dae"/>
      </geometry>
      <origin xyz="0.0 0.0 0.0" rpy="3.14 0 1.57"/>
    </collision>
  </link>

  <link name="left_ring_distal">
    <inertial>
      <mass value=".0010"/>
      <inertia ixx=".0010" ixy="0.0" ixz="0.0" iyy=".0010" iyz="0.0" izz=".0010"/>
    </inertial>
    <visual>
      <geometry>
        <mesh filename="package://r2_description/meshes/Finger_Dist.dae"/>
      </geometry>
      <origin xyz="0.0 0.0 0.0" rpy="0 -1.57 0"/>
    </visual>
    <collision>
      <geometry>
        <mesh filename="package://r2_description/meshes/Finger_Dist.dae"/>
      </geometry>
      <origin xyz="0.0 0.0 0.0" rpy="0 -1.57 0"/>
    </collision>
  </link>

  <link name="left_ring_tip">
    <inertial>
      <mass value=".0010"/>
      <inertia ixx=".0010" ixy="0.0" ixz="0.0" iyy=".0010" iyz="0.0" izz=".0010"/>
    </inertial>
  </link>


  <link name="left_little_proximal">
    <inertial>
      <mass value=".0010"/>
      <inertia ixx=".0010" ixy="0.0" ixz="0.0" iyy=".0010" iyz="0.0" izz=".0010"/>
    </inertial>
    <visual>
      <geometry>
        <mesh filename="package://r2_description/meshes/Finger_Proximal.dae"/>
      </geometry>
      <origin xyz="0.0 0.0 0.0" rpy="0 0 1.57"/>
    </visual>
    <collision>
      <geometry>
        <mesh filename="package://r2_description/meshes/Finger_Proximal.dae"/>
      </geometry>
      <origin xyz="0.0 0.0 0.0" rpy="0 0 1.57"/>
    </collision>
  </link>

  <link name="left_little_medial">
    <inertial>
      <mass value=".0010"/>
      <inertia ixx=".0010" ixy="0.0" ixz="0.0" iyy=".0010" iyz="0.0" izz=".0010"/>
    </inertial>
    <visual>
      <geometry>
        <mesh filename="package://r2_description/meshes/Finger_Mid.dae"/>
      </geometry>
      <origin xyz="0.0 0.0 0.0" rpy="3.14 0 1.57"/>
    </visual>
    <collision>
      <geometry>
        <mesh filename="package://r2_description/meshes/Finger_Mid.dae"/>
      </geometry>
      <origin xyz="0.0 0.0 0.0" rpy="3.14 0 1.57"/>
    </collision>
  </link>

  <link name="left_little_distal">
    <inertial>
      <mass value=".0010"/>
      <inertia ixx=".0010" ixy="0.0" ixz="0.0" iyy=".0010" iyz="0.0" izz=".0010"/>
    </inertial>
    <visual>
      <geometry>
        <mesh filename="package://r2_description/meshes/Finger_Dist.dae"/>
      </geometry>
      <origin xyz="0.0 0.0 0.0" rpy="0 -1.57 0"/>
    </visual>
    <collision>
      <geometry>
        <mesh filename="package://r2_description/meshes/Finger_Dist.dae"/>
      </geometry>
      <origin xyz="0.0 0.0 0.0" rpy="0 -1.57 0"/>
    </collision>
  </link>

  <link name="left_little_tip">
    <inertial>
      <mass value=".0010"/>
      <inertia ixx=".0010" ixy="0.0" ixz="0.0" iyy=".0010" iyz="0.0" izz=".0010"/>
    </inertial>
  </link>


<joint name="left_thumb/j0" type="revolute">
    <parent link="left_wrist_yaw"/>
    <child link="left_thumb_base"/>
    <origin xyz=" 0.03302 0.03048 0.00635 " rpy=" -1.57079632679 -0.0 1.30899702752 " />
    <axis xyz="0 0 1"/>
    <limit effort="10000000.0" lower="-1.2217" upper="0.0" velocity="1000"/>
    <dynamics damping="0.1" />
  </joint>
  <joint name="left_thumb/j1" type="fixed">
    <parent link="left_thumb_base"/>
    <child link="left_thumb_proximal"/>
    <origin xyz=" 0.011938 0.0 0.0 " rpy=" -1.570796 -0.0 0.0 " />
    <dynamics damping="0.1" />
  </joint>
  <joint name="left_thumb/j2" type="revolute">
    <parent link="left_thumb_proximal"/>
    <child link="left_thumb_medial_prime"/>
    <origin xyz=" 0.0 0.0 0.0 " rpy=" 0.0 -0.0 0.0 " />
    <axis xyz="0 0 1"/>
    <limit effort="10000000.0" lower="0.0" upper="1.3963" velocity="1000"/>
    <dynamics damping="0.1" />
  </joint>
  <joint name="left_thumb/j3" type="revolute">
    <parent link="left_thumb_medial_prime"/>
    <child link="left_thumb_medial"/>
    <origin xyz=" 0.030734 -0.001905 0.00254 " rpy=" -0.698132284627 -0.0 0.0 " />
    <axis xyz="0 0 1"/>
    <limit effort="10000000.0" lower="0.0" upper="1.2217" velocity="1000"/>
    <dynamics damping="0.1" />
  </joint>
  <joint name="left_thumb/j4" type="revolute">
    <parent link="left_thumb_medial"/>
    <child link="left_thumb_distal"/>
    <origin xyz=" 0.03937 0.0 0.0 " rpy=" 0.0 -0.0 0.0 " />
    <axis xyz="0 0 1"/>
    <limit effort="10000000.0" lower="-0.5236" upper="1.57" velocity="1000"/>
    <dynamics damping="0.1" />
  </joint>
  <joint name="left_thumb/j5" type="fixed">
    <parent link="left_thumb_distal"/>
    <child link="left_thumb_tip"/>
    <origin xyz=" 0.03302 0.0 0.0 " rpy=" 0.0 -0.0 0.0 " />
    <dynamics damping="0.1" />
  </joint>

  <joint name="left_index/j0" type="revolute">
    <parent link="left_wrist_yaw"/>
    <child link="left_index_base"/>
    <origin xyz=" 0.0994646728 0.0271119346 -0.0161544 " rpy=" 0.0 -0.0 0.122172725275 " />
    <axis xyz="0 0 1"/>
    <limit effort="10000000.0" lower="-0.3491" upper="0.3491" velocity="1000"/>
    <dynamics damping="0.1" />
  </joint>
  <joint name="left_index/j1" type="revolute">
    <parent link="left_index_base"/>
    <child link="left_index_proximal"/>
    <origin xyz=" 0.009652 0.0 0.0 " rpy=" 1.570796 0.0 0.0 " />
    <axis xyz="0 0 1"/>
    <limit effort="10000000.0" lower="0.0" upper="1.57" velocity="1000"/>
    <dynamics damping="0.1" />
  </joint>
  <joint name="left_index/j2" type="revolute">
    <parent link="left_index_proximal"/>
    <child link="left_index_medial"/>
    <origin xyz=" 0.04445 0.0 0.0 " rpy=" 0.0 -0.0 0.0 " />
    <axis xyz="0 0 1"/>
    <limit effort="10000000.0" lower="0.0" upper="1.57" velocity="1000"/>
    <dynamics damping="0.1" />
  </joint>
  <joint name="left_index/j3" type="revolute">
    <parent link="left_index_medial"/>
    <child link="left_index_distal"/>
    <origin xyz=" 0.03048 0.0 0.0 " rpy=" 0.0 -0.0 0.0 " />
    <axis xyz="0 0 1"/>
    <limit effort="10000000.0" lower="0.0" upper="1.57" velocity="1000"/>
    <dynamics damping="0.1" />
  </joint>
  <joint name="left_index/j4" type="fixed">
    <parent link="left_index_distal"/>
    <child link="left_index_tip"/>
    <origin xyz=" 0.024638 0.0 0.0 " rpy=" 0.0 -0.0 0.0 " />
    <dynamics damping="0.1" />
  </joint>

  <joint name="left_middle/j0" type="revolute">
    <parent link="left_wrist_yaw"/>
    <child link="left_middle_base"/>
    <origin xyz=" 0.10646537 0.00254 -0.0161544 " rpy=" 0.0 -0.0 0.0 " />
    <axis xyz="0 0 1"/>
    <limit effort="10000000.0" lower="-0.3491" upper="0.3491" velocity="1000"/>
    <dynamics damping="0.1" />
  </joint>
  <joint name="left_middle/j1" type="revolute">
    <parent link="left_middle_base"/>
    <child link="left_middle_proximal"/>
    <origin xyz=" 0.009652 0.0 0.0 " rpy=" 1.570796 -0.0 0.0 " />
    <axis xyz="0 0 1"/>
    <limit effort="10000000.0" lower="0.0" upper="1.57" velocity="1000"/>
    <dynamics damping="0.1" />
  </joint>
  <joint name="left_middle/j2" type="revolute">
    <parent link="left_middle_proximal"/>
    <child link="left_middle_medial"/>
    <origin xyz=" 0.04445 0.0 0.0 " rpy=" 0.0 -0.0 0.0 " />
    <axis xyz="0 0 1"/>
    <limit effort="10000000.0" lower="0.0" upper="1.57" velocity="1000"/>
    <dynamics damping="0.1" />
  </joint>
  <joint name="left_middle/j3" type="revolute">
    <parent link="left_middle_medial"/>
    <child link="left_middle_distal"/>
    <origin xyz=" 0.03048 0.0 0.0 " rpy=" 0.0 -0.0 0.0 " />
    <axis xyz="0 0 1"/>
    <limit effort="10000000.0" lower="0.0" upper="1.57" velocity="1000"/>
    <dynamics damping="0.1" />
  </joint>
  <joint name="left_middle/j4" type="fixed">
    <parent link="left_middle_distal"/>
    <child link="left_middle_tip"/>
    <origin xyz=" 0.024638 0.0 0.0 " rpy=" 0.0 -0.0 0.0 " />
    <dynamics damping="0.1" />
  </joint>

  <joint name="left_ring/j0" type="revolute">
    <parent link="left_wrist_yaw"/>
    <child link="left_ring_proximal"/>
    <origin xyz=" 0.1084570602 -0.0197673468 -0.012319 " rpy=" 1.57079632679 -0.0 -0.122172725275 " />
    <axis xyz="0 0 1"/>
    <limit effort="10000000.0" lower="0" upper="2.9671" velocity="1000"/>
    <dynamics damping="0.1" />
  </joint>
  <joint name="left_ring/j1" type="revolute">
    <parent link="left_ring_proximal"/>
    <child link="left_ring_medial"/>
    <origin xyz=" 0.04445 0.0 0.0 " rpy=" 0.0 -0.0 0.0 " />
    <axis xyz="0 0 1"/>
    <limit effort="10000000.0" lower="0" upper="2.9671" velocity="1000"/>
    <dynamics damping="0.1" />
  </joint>
  <joint name="left_ring/j2" type="revolute">
    <parent link="left_ring_medial"/>
    <child link="left_ring_distal"/>
    <origin xyz=" 0.03048 0.0 0.0 " rpy=" 0.0 -0.0 0.0 " />
    <axis xyz="0 0 1"/>	
    <limit effort="10000000.0" lower="0" upper="2.9671" velocity="1000"/>
    <dynamics damping="0.1" />
  </joint>
  <joint name="left_ring/j3" type="fixed">
    <parent link="left_ring_distal"/>
    <child link="left_ring_tip"/>
    <origin xyz=" 0.024638 0.0 0.0 " rpy=" 0.0 -0.0 0.0 " />
    <dynamics damping="0.1" />
  </joint>

  <joint name="left_little/j0" type="revolute">
    <parent link="left_wrist_yaw"/>
    <child link="left_little_proximal"/>
    <origin xyz=" 0.094635701 -0.0403792436 -0.0060878212 " rpy=" 1.60570321374 -0.0872667473393 -0.17453258148 " />
    <axis xyz="0 0 1"/>
    <limit effort="10000000.0" lower="0" upper="2.9671" velocity="1000"/>
    <dynamics damping="0.1" />
  </joint>
  <joint name="left_little/j1" type="revolute">
    <parent link="left_little_proximal"/>
    <child link="left_little_medial"/>
    <origin xyz=" 0.04445 0.0 0.0 " rpy=" 0.0 -0.0 0.0 " />
    <axis xyz="0 0 1"/>
    <limit effort="10000000.0" lower="0" upper="2.9671" velocity="1000"/>
    <dynamics damping="0.1" />
  </joint>
  <joint name="left_little/j2" type="revolute">
    <parent link="left_little_medial"/>
    <child link="left_little_distal"/>
    <origin xyz=" 0.03048 0.0 0.0 " rpy=" 0.0 -0.0 0.0 " />
    <axis xyz="0 0 1"/>
    <limit effort="10000000.0" lower="0" upper="2.9671" velocity="1000"/>
    <dynamics damping="0.1" />
  </joint>
  <joint name="left_little/j3" type="fixed">
    <parent link="left_little_distal"/>
    <child link="left_little_tip"/>
    <origin xyz=" 0.024638 0.0 0.0 " rpy=" 0.0 -0.0 0.0 " />
    <dynamics damping="0.1" />
  </joint>

</robot>
