<?xml version="1.0"?>
<robot>

  <link name="right_shoulder_roll">
    <visual>
      <geometry>
        <mesh filename="package://r2_description/meshes/Right_Shoulder_Upper.dae"/>
      </geometry>
      <material name="dirty_white"/>
      <origin rpy="0 0 2.25" xyz="0 0 .0254"/>
    </visual>
    <collision>
      <geometry>
        <mesh filename="package://r2_description/meshes/Right_Shoulder_Upper.dae"/>
      </geometry>
      <origin rpy="0 0 2.35" xyz="0 0 .0254"/>
    </collision>
    <inertial>
        <origin xyz="0.0089916 -0.00131572  0.10287"/>
        <mass value="6.168856232"/>
        <inertia ixx="0.0198585269"  ixy="0.0060195977"  ixz="0.0003950635"  iyy="0.0671900643"  iyz="0.00012683"  izz="0.0634150128"/>
    </inertial>
  </link>

<!--
  <link name="right_shoulder_roll_mass"/>
-->

  <link name="right_shoulder_pitch">
    <visual>
      <geometry>
        <mesh filename="package://r2_description/meshes/Right_Shoulder_Lower.dae"/>
      </geometry>
      <material name="dirty_white"/>
      <origin rpy=".0 0 1.57" xyz="0 0 0"/>
    </visual>
    <collision>
      <geometry>
        <mesh filename="package://r2_description/meshes/Right_Shoulder_Lower.dae"/>
      </geometry>
      <origin rpy=".0 0 1.57" xyz="0 0 0"/>
    </collision>
     <inertial>
        <origin xyz="0.0077978 0.037084 0.00028448"/>
        <mass value="4.4270615312"/>
        <inertia ixx="0.0113836825"  ixy="-.0000217138622526"  ixz="-.001512947"  iyy="0.0251962741"  iyz="-0.000052382497887"  izz="0.02701064"/>
    </inertial>
  </link>

<!--
  <link name="right_shoulder_pitch_mass"/>
-->

  <link name="right_upper_arm">
    <visual>
      <geometry>
        <mesh filename="package://r2_description/meshes/Right_Upper_Arm.dae"/>
      </geometry>
      <material name="dirty_white"/>
      <origin rpy="0 0 0" xyz="0 0 .1016"/>
    </visual>
    <collision>
       <geometry>
        <mesh filename="package://r2_description/meshes/Right_Upper_Arm.dae"/>
      </geometry>
      <origin rpy="0 0 0" xyz="0 0 .1016"/>
    </collision>
    <inertial>
        <origin xyz="0.041402  -0.0074168  0.1016"/>
        <mass value="4.853438359"/>
        <inertia ixx="0.04214011"  ixy="-0.0013754064"  ixz="-0.0065843922"  iyy="0.0462370652"  iyz="-0.00339462"  izz="0.016007389"/>
    </inertial>
  </link>

<!--
  <link name="right_upper_arm_mass"/>
-->

  <link name="right_elbow">
    <visual>
      <geometry>
        <mesh filename="package://r2_description/meshes/Right_Elbow.dae"/>
      </geometry>
      <material name="dirty_white"/>
      <origin rpy="0 0 1.57" xyz="0 0 0"/>
    </visual>
    <collision>
      <geometry>
        <mesh filename="package://r2_description/meshes/Right_Elbow.dae"/>
      </geometry>
      <origin rpy="0 0 1.57" xyz="0 0 0"/>
    </collision>
    <inertial>
        <origin xyz=" -0.026162  0.033782 0.0154432"/>
        <mass value="2.9710300235"/>
        <inertia ixx="0.0120274897"  ixy="-0.001188117"  ixz="0.0016417085"  iyy="0.0088377175"  iyz="-0.0031605083"  izz="0.0105350275"/>
    </inertial>
  </link>

<!--
  <link name="right_elbow_mass"/>
-->

  <link name="right_lower_arm">
    <visual>
      <geometry>
        <mesh filename="package://r2_description/meshes/Right_Forearm.dae"/>
      </geometry>
      <material name="dirty_white"/>
      <origin xyz="0 0 0.1"/>
    </visual>
    <collision>
      <geometry>
        <mesh filename="package://r2_description/meshes/Right_Forearm.dae"/>
      </geometry>
      <origin xyz="0 0 0.1"/>
    </collision>
    <inertial>
        <origin xyz="0.0003556 -0.00122682 0.17653"/>
        <mass value="6.939963261"/>
        <inertia ixx="0.0125249771"  ixy="0.0002446467"  ixz="0.0005208986"  iyy="0.0395063532"  iyz="0.0001691457"  izz="0.0403842721"/>
    </inertial>
  </link>

<!--
  <link name="right_lower_arm_mass"/>
-->

  <link name="right_wrist_pitch">
    <inertial>
        <origin xyz="0.00092202 -0.004064 0.000000152908"/>
        <mass value="0.1165732391"/>
        <inertia ixx=".0000169438359087"  ixy=".000000054430975458"  ixz="-.000000000043603308297"  iyy=".000044188587603"  iyz="-.00000175876431453"  izz=".00005765"/>
    </inertial>
  </link>

<!--
  <link name="right_wrist_pitch_mass"/>
-->

  <link name="right_wrist_yaw">
    <inertial>
        <origin xyz="0.067564 0.00090932 0.0253746"/>
        <mass value="1.1884120094"/>
        <inertia ixx="0.001992876"  ixy="-0.0001024239"  ixz="-0.000101546"  iyy="0.0044481227"  iyz="0.0003716524"  izz="0.0030141884"/>
    </inertial>
  </link>

<!--
  <link name="right_wrist_yaw_mass"/>
-->

  <link name="right_palm">
    <visual>
      <geometry>
        <mesh filename="package://r2_description/meshes/Right_Palm.dae"/>
      </geometry>
      <origin xyz="0.0 0.0 -0.0" rpy="3.14 0 1.57"/>
    </visual>
    <collision>
      <geometry>
        <mesh filename="package://r2_description/meshes/Right_Palm.dae"/>
      </geometry>
      <origin xyz="0.0 0.0 -0.0" rpy="3.14 0 1.57"/>
    </collision>
    <inertial>
      <mass value="0.1"/>
      <inertia ixx=".0010" ixy="0.0" ixz="0.0" iyy=".0010" iyz="0.0" izz=".0010"/>
    </inertial>
  </link>

  <joint name="right/j0" type="revolute">
    <parent link="chest_base"/>
    <child link="right_shoulder_roll"/>
    <origin rpy=" -1.5596 -0.0 -0.26157" xyz=" 0.0 -0.0 0.0"/>
    <axis xyz="0 0 1"/>
    <dynamics damping="10.0" />
    <limit effort="100.0" lower="-1.57" upper="1.57" velocity="1000"/>
  </joint>
  <joint name="right/j1" type="revolute">
    <parent link="right_shoulder_roll"/>
    <child link="right_shoulder_pitch"/>
    <origin rpy=" 1.5637 -0.0 -1.570796" xyz=" 0.0 -0.0 0.320929"/>
    <axis xyz="0 0 1"/>
    <dynamics damping="10.0" />
    <limit effort="100.0" lower="-1.66" upper=".175" velocity="1000"/>
  </joint>
  <joint name="right/j2" type="revolute">
    <parent link="right_shoulder_pitch"/>
    <child link="right_upper_arm"/>
    <origin rpy=" -1.5679 -0.0 0.0" xyz=" 0.0 0.0 0.0"/>
    <axis xyz="0 0 1"/>
    <dynamics damping="1.0" />
    <!-- limits expanded because Gazebo starts up at zero causing stability issues-->
<!--    <limit effort="100.0" lower="0.785" upper="4.89" velocity="1000"/>-->
    <limit effort="100.0" lower="0.0" upper="5.675" velocity="1000"/>
  </joint>
  <joint name="right/j3" type="revolute">
    <parent link="right_upper_arm"/>
    <child link="right_elbow"/>
    <origin rpy=" 1.5684 -0.0 0.0" xyz=" 0.0536067 0.0 0.355219"/>
    <axis xyz="0 0 1"/>
    <dynamics damping="1.0" />
    <!-- limits expanded because Gazebo starts up at zero causing stability issues-->
<!--    <limit effort="100.0" lower="-2.79" upper="-.087" velocity="1000"/>-->
    <limit effort="100.0" lower="-2.877" upper="0.0" velocity="1000"/>
  </joint>
  <joint name="right/j4" type="revolute">
    <parent link="right_elbow"/>
    <child link="right_lower_arm"/>
    <origin rpy=" -1.5656 -0.0 0.0" xyz=" -0.0537464 -0.0 0.0"/>
    <axis xyz="0 0 1"/>
    <dynamics damping="1.0" />
    <limit effort="100.0" lower="-4.45" upper="1.31" velocity="1000"/>
  </joint>
  <joint name="right/j5" type="revolute">
    <parent link="right_lower_arm"/>
    <child link="right_wrist_pitch"/>
    <origin rpy=" 1.5329 -0.0 0.0" xyz=" 0.0 0.0 0.3569462"/>
    <axis xyz="0 0 1"/>
    <dynamics damping="1.0" />
    <limit effort="100.0" lower="-1.22" upper="1.22" velocity="1000"/>
  </joint>
  <joint name="right/j6" type="revolute">
    <parent link="right_wrist_pitch"/>
    <child link="right_wrist_yaw"/>
    <origin rpy=" 1.5612 -0.0 1.5923" xyz=" -0.000139607 0.006491247 0.0"/>
    <axis xyz="0 0 1"/>
    <dynamics damping="1.0" />
    <limit effort="100.0" lower="-0.785" upper="0.785" velocity="1000"/>
  </joint>
  <joint name="right/j7" type="fixed">
    <parent link="right_wrist_yaw"/>
    <child link="right_palm"/>
    <origin rpy=" 0.0 -0.0 0.0299" xyz=" 0.0 0.0 0.0"/>
  </joint>

<!--
  <joint name="right/m0" type="fixed">
    <parent link="right_shoulder_roll"/>
    <child link="right_shoulder_roll_mass"/>
    <origin xyz="0.0089916 -0.00131572  0.10287   "/>
  </joint>

<joint name="right/m1" type="fixed">
    <parent link="right_shoulder_pitch"/>
    <child link="right_shoulder_pitch_mass"/>
    <origin xyz="   0.0077978   0.037084 0.00028448"/>
  </joint>

<joint name="right/m2" type="fixed">
    <parent link="right_upper_arm"/>
    <child link="right_upper_arm_mass"/>
    <origin xyz="   0.041402  -0.0074168  0.1016   "/>
  </joint>

<joint name="right/m3" type="fixed">
    <parent link="right_elbow"/>
    <child link="right_elbow_mass"/>
    <origin xyz=" -0.026162  0.033782 0.0154432  "/>
  </joint>

<joint name="right/m4" type="fixed">
    <parent link="right_lower_arm"/>
    <child link="right_lower_arm_mass"/>
    <origin xyz="0.0003556 -0.00122682   0.17653   "/>
  </joint>

<joint name="right/m5" type="fixed">
    <parent link="right_wrist_pitch"/>
    <child link="right_wrist_pitch_mass"/>
    <origin xyz="0.00092202 -0.004064   0.000000152908  "/>
  </joint>

<joint name="right/m6" type="fixed">
    <parent link="right_wrist_yaw"/>
    <child link="right_wrist_yaw_mass"/>
    <origin xyz="0.067564 0.00090932 0.0253746   "/>
  </joint>
-->
</robot>
