<?xml version="1.0"?>
<robot>

  <link name="right_thumb_base">
    <inertial>
      <mass value=".05"/>
      <inertia ixx=".0010" ixy="0.0" ixz="0.0" iyy=".0010" iyz="0.0" izz=".0010"/>
    </inertial>
  </link>

  <link name="right_thumb_proximal">
    <inertial>
      <mass value=".05"/>
      <inertia ixx=".0010" ixy="0.0" ixz="0.0" iyy=".0010" iyz="0.0" izz=".0010"/>
    </inertial>
    <visual>
      <geometry>
        <mesh filename="package://r2_description/meshes/Left_Thumb_Carp.dae"/>
      </geometry>
      <origin xyz="-0.01 0.0 0.0" rpy="-1.57 0 0"/>
    </visual>
    <collision>
      <geometry>
        <mesh filename="package://r2_description/meshes/Left_Thumb_Carp.dae" scale="0.9 0.9 0.9"/>
      </geometry>
      <origin xyz="-0.01 0.0 0.0" rpy="-1.57 0 0"/>
    </collision>
  </link>

  <link name="right_thumb_medial_prime">
    <inertial>
      <mass value=".05"/>
      <inertia ixx=".0010" ixy="0.0" ixz="0.0" iyy=".0010" iyz="0.0" izz=".0010"/>
    </inertial>
    <visual>
       <geometry>
        <mesh filename="package://r2_description/meshes/Right_Thumb_MtCar.dae"/>
      </geometry>
      <origin xyz="-0.0 0 0.0" rpy="-1.57 -1.57 0 "/>
    </visual>
    <collision>
      <geometry>
        <mesh filename="package://r2_description/meshes/Right_Thumb_MtCar.dae" scale="0.9 0.9 0.9"/>
      </geometry>
      <origin xyz="-0.0 0 0.0" rpy="-1.57 -1.57 0 "/>
    </collision>
  </link>

  <link name="right_thumb_medial">
    <inertial>
      <mass value=".05"/>
      <inertia ixx=".0010" ixy="0.0" ixz="0.0" iyy=".0010" iyz="0.0" izz=".0010"/>
    </inertial>
    <visual>
       <geometry>
        <mesh filename="package://r2_description/meshes/Thumb_Proximal.dae"/>
      </geometry>
      <origin xyz="0.0 0.0 0.0" rpy="3.14 0 1.57"/>
    </visual>
    <collision>
      <geometry>
        <mesh filename="package://r2_description/meshes/Thumb_Proximal.dae"/>
      </geometry>
      <origin xyz="0.0 0.0 0.0" rpy="3.14 0 1.57"/>
    </collision>
  </link>

  <link name="right_thumb_distal">
    <inertial>
      <mass value=".05"/>
      <inertia ixx=".0010" ixy="0.0" ixz="0.0" iyy=".0010" iyz="0.0" izz=".0010"/>
    </inertial>
    <visual>
       <geometry>
        <mesh filename="package://r2_description/meshes/Thumb_Dist.dae"/>
      </geometry>
      <origin xyz="0.0 0.0 0.0" rpy="3.14 3.14 0"/>
    </visual>
    <collision>
      <geometry>
        <mesh filename="package://r2_description/meshes/Thumb_Dist.dae"/>
      </geometry>
      <origin xyz="0.0 0.0 0.0" rpy="3.14 3.14 0"/>
    </collision>
  </link>

  <link name="right_thumb_tip">
    <inertial>
      <mass value=".05"/>
      <inertia ixx=".0010" ixy="0.0" ixz="0.0" iyy=".0010" iyz="0.0" izz=".0010"/>
    </inertial>
  </link>


  <link name="right_index_base">
    <inertial>
      <mass value=".05"/>
      <inertia ixx=".0010" ixy="0.0" ixz="0.0" iyy=".0010" iyz="0.0" izz=".0010"/>
    </inertial>
  </link>

  <link name="right_index_proximal">
    <inertial>
      <mass value=".05"/>
      <inertia ixx=".0010" ixy="0.0" ixz="0.0" iyy=".0010" iyz="0.0" izz=".0010"/>
    </inertial>
    <visual>
      <geometry>
        <mesh filename="package://r2_description/meshes/Finger_Proximal.dae"/>
      </geometry>
      <origin xyz="0.0 0.0 0.0" rpy="0 0 1.57"/>
    </visual>
    <collision>
      <geometry>
        <mesh filename="package://r2_description/meshes/Finger_Proximal.dae"/>
      </geometry>
      <origin xyz="0.0 0.0 0.0" rpy="0 0 1.57"/>
    </collision>
  </link>

  <link name="right_index_medial">
    <inertial>
      <mass value=".05"/>
      <inertia ixx=".0010" ixy="0.0" ixz="0.0" iyy=".0010" iyz="0.0" izz=".0010"/>
    </inertial>
    <visual>
      <geometry>
        <mesh filename="package://r2_description/meshes/Finger_Mid.dae"/>
      </geometry>
      <origin xyz="0.0 0.0 0.0" rpy="3.14 0 1.57"/>
    </visual>
    <collision>
      <geometry>
        <mesh filename="package://r2_description/meshes/Finger_Mid.dae"/>
      </geometry>
      <origin xyz="0.0 0.0 0.0" rpy="3.14 0 1.57"/>
    </collision>
  </link>

  <link name="right_index_distal">
    <inertial>
      <mass value=".05"/>
      <inertia ixx=".0010" ixy="0.0" ixz="0.0" iyy=".0010" iyz="0.0" izz=".0010"/>
    </inertial>
    <visual>
      <geometry>
        <mesh filename="package://r2_description/meshes/Finger_Dist.dae"/>
      </geometry>
      <origin xyz="0.0 0.0 0.0" rpy="0 -1.57 0"/>
    </visual>
    <collision>
      <geometry>
        <mesh filename="package://r2_description/meshes/Finger_Dist.dae"/>
      </geometry>
      <origin xyz="0.0 0.0 0.0" rpy="0 -1.57 0"/>
    </collision>
  </link>

  <link name="right_index_tip">
    <inertial>
      <mass value=".05"/>
      <inertia ixx=".0010" ixy="0.0" ixz="0.0" iyy=".0010" iyz="0.0" izz=".0010"/>
    </inertial>
  </link>


   <link name="right_middle_base">
    <inertial>
      <mass value=".0010"/>
      <inertia ixx=".0010" ixy="0.0" ixz="0.0" iyy=".0010" iyz="0.0" izz=".0010"/>
    </inertial>
  </link>

  <link name="right_middle_proximal">
    <inertial>
      <mass value=".05"/>
      <inertia ixx=".0010" ixy="0.0" ixz="0.0" iyy=".0010" iyz="0.0" izz=".0010"/>
    </inertial>
    <visual>
      <geometry>
        <mesh filename="package://r2_description/meshes/Finger_Proximal.dae"/>
      </geometry>
      <origin xyz="0.0 0.0 0.0" rpy="0 0 1.57"/>
    </visual>
    <collision>
      <geometry>
        <mesh filename="package://r2_description/meshes/Finger_Proximal.dae" scale="0.9 0.9 0.9"/>
      </geometry>
      <origin xyz="0.0 0.0 0.0" rpy="0 0 1.57"/>
    </collision>
  </link>

  <link name="right_middle_medial">
    <inertial>
      <mass value=".05"/>
      <inertia ixx=".0010" ixy="0.0" ixz="0.0" iyy=".0010" iyz="0.0" izz=".0010"/>
    </inertial>
    <visual>
      <geometry>
        <mesh filename="package://r2_description/meshes/Finger_Mid.dae"/>
      </geometry>
      <origin xyz="0.0 0.0 0.0" rpy="3.14 0 1.57"/>
    </visual>
    <collision>
      <geometry>
        <mesh filename="package://r2_description/meshes/Finger_Mid.dae" scale="0.9 0.9 0.9"/>
      </geometry>
      <origin xyz="0.0 0.0 0.0" rpy="3.14 0 1.57"/>
    </collision>
  </link>

  <link name="right_middle_distal">
    <inertial>
      <mass value=".05"/>
      <inertia ixx=".0010" ixy="0.0" ixz="0.0" iyy=".0010" iyz="0.0" izz=".0010"/>
    </inertial>
    <visual>
      <geometry>
        <mesh filename="package://r2_description/meshes/Finger_Dist.dae"/>
      </geometry>
      <origin xyz="0.0 0.0 0.0" rpy="0 -1.57 0"/>
    </visual>
    <collision>
      <geometry>
        <mesh filename="package://r2_description/meshes/Finger_Dist.dae" scale="0.9 0.9 0.9"/>
      </geometry>
      <origin xyz="0.0 0.0 0.0" rpy="0 -1.57 0"/>
    </collision>
  </link>

  <link name="right_middle_tip">
    <inertial>
      <mass value=".05"/>
      <inertia ixx=".0010" ixy="0.0" ixz="0.0" iyy=".0010" iyz="0.0" izz=".0010"/>
    </inertial>
  </link>
  

  <link name="right_ring_proximal">
    <inertial>
      <mass value=".05"/>
      <inertia ixx=".0010" ixy="0.0" ixz="0.0" iyy=".0010" iyz="0.0" izz=".0010"/>
    </inertial>
    <visual>
      <geometry>
        <mesh filename="package://r2_description/meshes/Finger_Proximal.dae"/>
      </geometry>
      <origin xyz="0.0 0.0 0.0" rpy="0 0 1.57"/>
    </visual>
    <collision>
      <geometry>
        <mesh filename="package://r2_description/meshes/Finger_Proximal.dae" scale="0.9 0.9 0.9"/>
      </geometry>
      <origin xyz="0.0 0.0 0.0" rpy="0 0 1.57"/>
    </collision>
  </link>

  <link name="right_ring_medial">
    <inertial>
      <mass value=".05"/>
      <inertia ixx=".0010" ixy="0.0" ixz="0.0" iyy=".0010" iyz="0.0" izz=".0010"/>
    </inertial>
    <visual>
      <geometry>
        <mesh filename="package://r2_description/meshes/Finger_Mid.dae"/>
      </geometry>
      <origin xyz="0.0 0.0 0.0" rpy="3.14 0 1.57"/>
    </visual>
    <collision>
      <geometry>
        <mesh filename="package://r2_description/meshes/Finger_Mid.dae" scale="0.9 0.9 0.9"/>
      </geometry>
      <origin xyz="0.0 0.0 0.0" rpy="3.14 0 1.57"/>
    </collision>
  </link>

  <link name="right_ring_distal">
    <inertial>
      <mass value=".05"/>
      <inertia ixx=".0010" ixy="0.0" ixz="0.0" iyy=".0010" iyz="0.0" izz=".0010"/>
    </inertial>
    <visual>
      <geometry>
        <mesh filename="package://r2_description/meshes/Finger_Dist.dae"/>
      </geometry>
      <origin xyz="0.0 0.0 0.0" rpy="0 -1.57 0"/>
    </visual>
    <collision>
      <geometry>
        <mesh filename="package://r2_description/meshes/Finger_Dist.dae" scale="0.9 0.9 0.9"/>
      </geometry>
      <origin xyz="0.0 0.0 0.0" rpy="0 -1.57 0"/>
    </collision>
  </link>

  <link name="right_ring_tip">
    <inertial>
      <mass value=".05"/>
      <inertia ixx=".0010" ixy="0.0" ixz="0.0" iyy=".0010" iyz="0.0" izz=".0010"/>
    </inertial>
  </link>

  <link name="right_little_proximal">
    <inertial>
      <mass value=".05"/>
      <inertia ixx=".0010" ixy="0.0" ixz="0.0" iyy=".0010" iyz="0.0" izz=".0010"/>
    </inertial>
    <visual>
      <geometry>
        <mesh filename="package://r2_description/meshes/Finger_Proximal.dae"/>
      </geometry>
      <origin xyz="0.0 0.0 0.0" rpy="0 0 1.57"/>
    </visual>
    <collision>
      <geometry>
        <mesh filename="package://r2_description/meshes/Finger_Proximal.dae" scale="0.9 0.9 0.9"/>
      </geometry>
      <origin xyz="0.0 0.0 0.0" rpy="0 0 1.57"/>
    </collision>
  </link>

  <link name="right_little_medial">
    <inertial>
      <mass value=".05"/>
      <inertia ixx=".0010" ixy="0.0" ixz="0.0" iyy=".0010" iyz="0.0" izz=".0010"/>
    </inertial>
    <visual>
      <geometry>
        <mesh filename="package://r2_description/meshes/Finger_Mid.dae"/>
      </geometry>
      <origin xyz="0.0 0.0 0.0" rpy="3.14 0 1.57"/>
    </visual>
    <collision>
      <geometry>
        <mesh filename="package://r2_description/meshes/Finger_Mid.dae" scale="0.9 0.9 0.9"/>
      </geometry>
      <origin xyz="0.0 0.0 0.0" rpy="3.14 0 1.57"/>
    </collision>
  </link>

  <link name="right_little_distal">
    <inertial>
      <mass value=".05"/>
      <inertia ixx=".0010" ixy="0.0" ixz="0.0" iyy=".0010" iyz="0.0" izz=".0010"/>
    </inertial>
    <visual>
      <geometry>
        <mesh filename="package://r2_description/meshes/Finger_Dist.dae"/>
      </geometry>
      <origin xyz="0.0 0.0 0.0" rpy="0 -1.57 0"/>
    </visual>
    <collision>
      <geometry>
        <mesh filename="package://r2_description/meshes/Finger_Dist.dae" scale="0.9 0.9 0.9"/>
      </geometry>
      <origin xyz="0.0 0.0 0.0" rpy="0 -1.57 0"/>
    </collision>
  </link>

  <link name="right_little_tip">
    <inertial>
      <mass value=".05"/>
      <inertia ixx=".0010" ixy="0.0" ixz="0.0" iyy=".0010" iyz="0.0" izz=".0010"/>
    </inertial>
  </link>

<joint name="right_thumb/j0" type="revolute">
    <parent link="right_wrist_yaw"/>
    <child link="right_thumb_base"/>
    <origin xyz="0.03302 -0.03048 0.00635 " rpy=" 1.57079632679 0.174532791018 -1.30899687745 " />
    <axis xyz="0 0 1"/>
    <limit effort="10000000.0" lower="0.0" upper="1.2217" velocity="1000"/>
    <dynamics damping="0.1" />
  </joint>
  <joint name="right_thumb/j1" type="fixed">
    <parent link="right_thumb_base"/>
    <child link="right_thumb_proximal"/>
    <origin xyz=" 0.011938 0.0 0.0 " rpy=" -1.570796 -0.0 0.0 " />
    <dynamics damping="0.1" />
  </joint>
  <joint name="right_thumb/j2" type="revolute">
    <parent link="right_thumb_proximal"/>
    <child link="right_thumb_medial_prime"/>
    <origin xyz=" 0.0 0.0 0.0 " rpy=" 0.0 -0.0 0.0 " />
    <axis xyz="0 0 1"/>
    <limit effort="10000000.0" lower="0.0" upper="1.3963" velocity="1000"/>
    <dynamics damping="0.1" />
  </joint>
  <joint name="right_thumb/j3" type="revolute">
    <parent link="right_thumb_medial_prime"/>
    <child link="right_thumb_medial"/>
    <origin xyz=" 0.030734 -0.001905 -0.00254 " rpy=" 0.698132284627 -0.0 0.0 " />
    <axis xyz="0 0 1"/>
    <limit effort="10000000.0" lower="0.0" upper="1.2217" velocity="1000"/>
    <dynamics damping="0.1" />
  </joint>
  <joint name="right_thumb/j4" type="revolute">
    <parent link="right_thumb_medial"/>
    <child link="right_thumb_distal"/>
    <origin xyz=" 0.03937 0.0 0.0 " rpy=" 0.0 -0.0 0.0 " />
    <axis xyz="0 0 1"/>
    <limit effort="10000000.0" lower="-0.5236" upper="1.57" velocity="1000"/>
    <dynamics damping="0.1" />
  </joint>
  <joint name="right_thumb/j5" type="fixed">
    <parent link="right_thumb_distal"/>
    <child link="right_thumb_tip"/>
    <origin xyz=" 0.03302 0.0 0.0 " rpy=" 0.0 -0.0 0.0 " />
    <dynamics damping="0.1" />
  </joint>


  <joint name="right_index/j0" type="revolute">
    <parent link="right_wrist_yaw"/>
    <child link="right_index_base"/>
    <origin xyz=" 0.0994646728 -0.0271119346 -0.0161544 " rpy=" 0.0 -0.0 -0.122172725275  " />
    <axis xyz="0 0 1"/>
    <limit effort="10000000.0" lower="-0.3491" upper="0.3491" velocity="1000"/>
    <dynamics damping="0.1" />
  </joint>
  <joint name="right_index/j1" type="revolute">
    <parent link="right_index_base"/>
    <child link="right_index_proximal"/>
    <origin xyz=" 0.009652 0.0 0.0 " rpy=" 1.570796 -0.0 0.0 " />
    <axis xyz="0 0 1"/>
    <limit effort="10000000.0" lower="0.0" upper="1.57" velocity="1000"/>
    <dynamics damping="0.1" />
  </joint>
  <joint name="right_index/j2" type="revolute">
    <parent link="right_index_proximal"/>
    <child link="right_index_medial"/>
    <origin xyz=" 0.04445 0.0 0.0 " rpy=" 0.0 -0.0 0.0 " />
    <axis xyz="0 0 1"/>
    <limit effort="10000000.0" lower="0.0" upper="1.57" velocity="1000"/>
    <dynamics damping="0.1" />
  </joint>
  <joint name="right_index/j3" type="revolute">
    <parent link="right_index_medial"/>
    <child link="right_index_distal"/>
    <origin xyz=" 0.03048 0.0 0.0 " rpy=" 0.0 -0.0 0.0 " />
    <axis xyz="0 0 1"/>
    <limit effort="10000000.0" lower="0.0" upper="1.57" velocity="1000"/>
    <dynamics damping="0.1" />
  </joint>
  <joint name="right_index/j4" type="fixed">
    <parent link="right_index_distal"/>
    <child link="right_index_tip"/>
    <origin xyz=" 0.024638 0.0 0.0 " rpy=" 0.0 -0.0 0.0 " />
    <dynamics damping="0.1" />
  </joint>

  <joint name="right_middle/j0" type="revolute">
    <parent link="right_wrist_yaw"/>
    <child link="right_middle_base"/>
    <origin xyz="0.10646537 -0.00254 -0.0161544 " rpy=" 0.0 -0.0 0.0 " />
    <axis xyz="0 0 1"/>
    <limit effort="10000000.0" lower="-0.3491" upper="0.3491" velocity="1000"/>
    <dynamics damping="0.1" />
  </joint>
  <joint name="right_middle/j1" type="revolute">
    <parent link="right_middle_base"/>
    <child link="right_middle_proximal"/>
    <origin xyz=" 0.009652 0.0 0.0 " rpy=" 1.570796 -0.0 0.0 " />
    <axis xyz="0 0 1"/>
    <limit effort="10000000.0" lower="0.0" upper="1.57" velocity="1000"/>
    <dynamics damping="0.1" />
  </joint>
  <joint name="right_middle/j2" type="revolute">
    <parent link="right_middle_proximal"/>
    <child link="right_middle_medial"/>
    <origin xyz=" 0.04445 0.0 0.0 " rpy=" 0.0 -0.0 0.0 " />
    <axis xyz="0 0 1"/>
    <limit effort="10000000.0" lower="0.0" upper="1.57" velocity="1000"/>
    <dynamics damping="0.1" />
  </joint>
  <joint name="right_middle/j3" type="revolute">
    <parent link="right_middle_medial"/>
    <child link="right_middle_distal"/>
    <origin xyz=" 0.03048 0.0 0.0 " rpy=" 0.0 -0.0 0.0 " />
    <axis xyz="0 0 1"/>
    <limit effort="10000000.0" lower="0.0" upper="1.57" velocity="1000"/>
    <dynamics damping="0.1" />
  </joint>
  <joint name="right_middle/j4" type="fixed">
    <parent link="right_middle_distal"/>
    <child link="right_middle_tip"/>
    <origin xyz=" 0.024638 0.0 0.0 " rpy=" 0.0 -0.0 0.0 " />
    <dynamics damping="0.1" />
  </joint>

  <joint name="right_ring/j0" type="revolute">
    <parent link="right_wrist_yaw"/>
    <child link="right_ring_proximal"/>
    <origin xyz=" 0.1084539614 0.019792569 -0.012319 " rpy=" 1.57079632679 -0.0 0.122172725275  " />
    <axis xyz="0 0 1"/>
    <limit effort="10000000.0" lower="0" upper="2.9671" velocity="1000"/>
    <dynamics damping="0.1" />
  </joint>
  <joint name="right_ring/j1" type="revolute">
    <parent link="right_ring_proximal"/>
    <child link="right_ring_medial"/>
    <origin xyz=" 0.04445 0.0 0.0 " rpy=" 0.0 -0.0 0.0 " />
    <axis xyz="0 0 1"/>
    <limit effort="10000000.0" lower="0" upper="2.9671" velocity="1000"/>
    <dynamics damping="0.1" />
  </joint>
  <joint name="right_ring/j2" type="revolute">
    <parent link="right_ring_medial"/>
    <child link="right_ring_distal"/>
    <origin xyz=" 0.03048 0.0 0.0 " rpy=" 0.0 -0.0 0.0 " />
    <axis xyz="0 0 1"/>
    <limit effort="10000000.0" lower="0" upper="2.9671" velocity="1000"/>
    <dynamics damping="0.1" />
  </joint>
  <joint name="right_ring/j3" type="fixed">
    <parent link="right_ring_distal"/>
    <child link="right_ring_tip"/>
    <origin xyz=" 0.024638 0.0 0.0 " rpy=" 0.0 -0.0 0.0 " />
    <dynamics damping="0.1" />
  </joint>

  <joint name="right_little/j0" type="revolute">
    <parent link="right_wrist_yaw"/>
    <child link="right_little_proximal"/>
    <origin xyz=" 0.094635701 0.0403792436 -0.0060878212 " rpy=" 1.53588943985 -0.0872667473393 0.17453258148  " />
    <axis xyz="0 0 1"/>
    <limit effort="10000000.0" lower="0" upper="2.9671" velocity="1000"/>
    <dynamics damping="0.1" />
  </joint>
  <joint name="right_little/j1" type="revolute">
    <parent link="right_little_proximal"/>
    <child link="right_little_medial"/>
    <origin xyz=" 0.04445 0.0 0.0 " rpy=" 0.0 -0.0 0.0 " />
    <axis xyz="0 0 1"/>
    <limit effort="10000000.0" lower="0" upper="2.9671" velocity="1000"/>
    <dynamics damping="0.1" />
  </joint>
  <joint name="right_little/j2" type="revolute">
    <parent link="right_little_medial"/>
    <child link="right_little_distal"/>
    <origin xyz=" 0.03048 0.0 0.0 " rpy=" 0.0 -0.0 0.0 " />
    <axis xyz="0 0 1"/>
    <limit effort="10000000.0" lower="0" upper="2.9671" velocity="1000"/>
    <dynamics damping="0.1" />
  </joint>
  <joint name="right_little/j3" type="fixed">
    <parent link="right_little_distal"/>
    <child link="right_little_tip"/>
    <origin xyz=" 0.024638 0.0 0.0 " rpy=" 0.0 -0.0 0.0 " />
    <dynamics damping="0.1" />
  </joint>

</robot>
